Workbook

Sheet Tracker
A1: Tooling Number | B1: Part Number | C1: Location | D1: Driver Found? | E1: Driver Number | F1: Tooling Documentation in Agile? | G1: Driver Documentation in Agile? | H1: Notes | I1: Date Complete | J1: Sort Key
A2: 208862 | B2: 304134 304371 10001073 | C2: A1-A18 | D2: ☑ | E2: Box 1 | F2: ☑ | G2: ☐ | H2: driver files not in agile | J2: =IF($C2="","",LEFT($C2,1)&TEXT(VALUE(MID($C2,2,IFERROR(FIND("-",$C2),LEN($C2)+1)-2)),"000")) -> A001
A3: 207476 | B3: 304009 | C3: A19-A26 | D3: ☑ | E3: 203149 | F3: ☑ | G3: ☐ | H3: blue driver box | J3: =IF($C3="","",LEFT($C3,1)&TEXT(VALUE(MID($C3,2,IFERROR(FIND("-",$C3),LEN($C3)+1)-2)),"000")) -> A019
A4: 207771 | B4: 304232 304016 304116 304315 | C4: A27-A30 | D4: ☑ | E4: 203149 | F4: ☑ | G4: ☐ | H4: blue driver box | J4: =IF($C4="","",LEFT($C4,1)&TEXT(VALUE(MID($C4,2,IFERROR(FIND("-",$C4),LEN($C4)+1)-2)),"000")) -> A027
A5: 216120 | B5: 304761 405378 | C5: A31-A45 | D5: ☑ | E5: Box 2 | F5: ☑ | G5: ☐ | H5: driver # not on box | J5: =IF($C5="","",LEFT($C5,1)&TEXT(VALUE(MID($C5,2,IFERROR(FIND("-",$C5),LEN($C5)+1)-2)),"000")) -> A031
A6: 10003054 | B6: 10002940 | C6: A46-A60 | D6: ☑ | E6: Box 3 | F6: ☑ | G6: ☐ | H6: driver # not on box | J6: =IF($C6="","",LEFT($C6,1)&TEXT(VALUE(MID($C6,2,IFERROR(FIND("-",$C6),LEN($C6)+1)-2)),"000")) -> A046
A7: 210053 | B7: 304261 304262 | C7: C61-C75 | D7: ☑ | E7: Box 4 | F7: ☑ | G7: ☐ | H7: driver # not on box | J7: =IF($C7="","",LEFT($C7,1)&TEXT(VALUE(MID($C7,2,IFERROR(FIND("-",$C7),LEN($C7)+1)-2)),"000")) -> C061
A8: 210792 | B8: 403262 404380 | C8: B1-B4 | D8: ☑ | E8: Box 2 | F8: ☑ | G8: ☐ | H8: driver # not on box | J8: =IF($C8="","",LEFT($C8,1)&TEXT(VALUE(MID($C8,2,IFERROR(FIND("-",$C8),LEN($C8)+1)-2)),"000")) -> B001
A9: 210766 | B9: 403263 404381 404900 | C9: B5-B8 | D9: ☑ | E9: Box 2 | F9: ☑ | G9: ☐ | H9: driver # not on box | J9: =IF($C9="","",LEFT($C9,1)&TEXT(VALUE(MID($C9,2,IFERROR(FIND("-",$C9),LEN($C9)+1)-2)),"000")) -> B005
A10: 213868 | B10: 404379 404397 404399 | C10: B9-B12 | D10: ☑ | E10: 213679 | F10: ☑ | G10: ☑ | I10: 46224 | J10: =IF($C10="","",LEFT($C10,1)&TEXT(VALUE(MID($C10,2,IFERROR(FIND("-",$C10),LEN($C10)+1)-2)),"000")) -> B009
A11: 210787 | B11: 304265 403260 | C11: B13-B15 | D11: ☑ | E11: Box 2 | F11: ☑ | G11: ☐ | H11: driver # not on box | J11: =IF($C11="","",LEFT($C11,1)&TEXT(VALUE(MID($C11,2,IFERROR(FIND("-",$C11),LEN($C11)+1)-2)),"000")) -> B013
A12: 208488 | B12: 304121 | C12: B16-B19 | D12: ☑ | E12: 203149 | F12: ☑ | G12: ☐ | H12: blue driver box | J12: =IF($C12="","",LEFT($C12,1)&TEXT(VALUE(MID($C12,2,IFERROR(FIND("-",$C12),LEN($C12)+1)-2)),"000")) -> B016
A13: 208791 | B13: 304122 | C13: B20-B21 | D13: ☑ | E13: Box 5 | F13: ☑ | G13: ☐ | H13: driver # not on box | J13: =IF($C13="","",LEFT($C13,1)&TEXT(VALUE(MID($C13,2,IFERROR(FIND("-",$C13),LEN($C13)+1)-2)),"000")) -> B020
A14: 208793 | B14: 304124 | C14: B22-B23 | D14: ☑ | E14: Box 5 | F14: ☑ | G14: ☐ | H14: driver # not on box | J14: =IF($C14="","",LEFT($C14,1)&TEXT(VALUE(MID($C14,2,IFERROR(FIND("-",$C14),LEN($C14)+1)-2)),"000")) -> B022
A15: 208794 | B15: 304125 | C15: B24-B25 | D15: ☑ | E15: Box 5 | F15: ☑ | G15: ☐ | H15: driver # not on box | J15: =IF($C15="","",LEFT($C15,1)&TEXT(VALUE(MID($C15,2,IFERROR(FIND("-",$C15),LEN($C15)+1)-2)),"000")) -> B024
A16: 208795 | B16: 304126 | C16: B26-B27 | D16: ☑ | E16: Box 5 | F16: ☑ | G16: ☐ | H16: driver # not on box | J16: =IF($C16="","",LEFT($C16,1)&TEXT(VALUE(MID($C16,2,IFERROR(FIND("-",$C16),LEN($C16)+1)-2)),"000")) -> B026
A17: 209442 | B17: 402980 | C17: B28-B31 | D17: ☑ | E17: Box 6 | F17: ☑ | G17: ☐ | H17: driver # not on box | J17: =IF($C17="","",LEFT($C17,1)&TEXT(VALUE(MID($C17,2,IFERROR(FIND("-",$C17),LEN($C17)+1)-2)),"000")) -> B028
A18: 209126 | B18: 304139 304233 304386 | C18: B32-B35 | D18: ☑ | E18: Box 5 | F18: ☑ | G18: ☐ | H18: driver # not on box | J18: =IF($C18="","",LEFT($C18,1)&TEXT(VALUE(MID($C18,2,IFERROR(FIND("-",$C18),LEN($C18)+1)-2)),"000")) -> B032
A19: 208862 | B19: 304217 304568 304674 | C19: B36-B42 | D19: ☑ | E19: Box 5 | F19: ☑ | G19: ☐ | H19: driver # not on box | J19: =IF($C19="","",LEFT($C19,1)&TEXT(VALUE(MID($C19,2,IFERROR(FIND("-",$C19),LEN($C19)+1)-2)),"000")) -> B036
A20: 208792 | B20: 304123 402981 | C20: B43-B45 | D20: ☑ | E20: Box 5 | F20: ☑ | G20: ☐ | H20: driver # not on box | J20: =IF($C20="","",LEFT($C20,1)&TEXT(VALUE(MID($C20,2,IFERROR(FIND("-",$C20),LEN($C20)+1)-2)),"000")) -> B043
A21: 208623 | B21: 304138 | C21: B46-B50 | D21: ☑ | E21: 203149 | F21: ☑ | G21: ☐ | H21: blue driver box | J21: =IF($C21="","",LEFT($C21,1)&TEXT(VALUE(MID($C21,2,IFERROR(FIND("-",$C21),LEN($C21)+1)-2)),"000")) -> B046
A22: 211264 | B22: 304314 | C22: B51-B52 | D22: ☑ | E22: Box 7 | F22: ☑ | G22: ☐ | H22: driver # not on box | J22: =IF($C22="","",LEFT($C22,1)&TEXT(VALUE(MID($C22,2,IFERROR(FIND("-",$C22),LEN($C22)+1)-2)),"000")) -> B051
A23: 211217 | B23: 403479 | C23: B54-B55 | D23: ☑ | E23: 211217 | F23: ☑ | G23: ☑ | I23: 46224 | J23: =IF($C23="","",LEFT($C23,1)&TEXT(VALUE(MID($C23,2,IFERROR(FIND("-",$C23),LEN($C23)+1)-2)),"000")) -> B054
A24: 211377 | B24: 403480 | C24: B56-B57 | D24: ☑ | E24: 211217 | F24: ☑ | G24: ☑ | I24: 46223 | J24: =IF($C24="","",LEFT($C24,1)&TEXT(VALUE(MID($C24,2,IFERROR(FIND("-",$C24),LEN($C24)+1)-2)),"000")) -> B056
A25: 211496 | B25: 403481 | C25: B58-B59 | D25: ☑ | E25: 211496 | F25: ☑ | G25: ☑ | I25: 46223 | J25: =IF($C25="","",LEFT($C25,1)&TEXT(VALUE(MID($C25,2,IFERROR(FIND("-",$C25),LEN($C25)+1)-2)),"000")) -> B058
A26: 213849 | B26: 404309 404310 | C26: B60-B64 | D26: ☑ | E26: Box 8 | F26: ☑ | G26: ☐ | H26: driver # not on box | J26: =IF($C26="","",LEFT($C26,1)&TEXT(VALUE(MID($C26,2,IFERROR(FIND("-",$C26),LEN($C26)+1)-2)),"000")) -> B060
A27: 201923 | B27: 401063 402268 402362 404162 | C27: B65-B71 | D27: ☑ | E27: 203149 | F27: ☑ | G27: ☐ | H27: blue driver box | J27: =IF($C27="","",LEFT($C27,1)&TEXT(VALUE(MID($C27,2,IFERROR(FIND("-",$C27),LEN($C27)+1)-2)),"000")) -> B065
A28: 210062 | B28: 304290 | C28: B73-B74 | D28: ☑ | E28: Box 4 | F28: ☑ | G28: ☐ | H28: driver # not on box | J28: =IF($C28="","",LEFT($C28,1)&TEXT(VALUE(MID($C28,2,IFERROR(FIND("-",$C28),LEN($C28)+1)-2)),"000")) -> B073
A29: 215663 | B29: 304734 | C29: C1-C8 | D29: ☑ | E29: 215577 | F29: ☑ | G29: ☑ | I29: 46224 | J29: =IF($C29="","",LEFT($C29,1)&TEXT(VALUE(MID($C29,2,IFERROR(FIND("-",$C29),LEN($C29)+1)-2)),"000")) -> C001
A30: 215577 | B30: 304735 | C30: C9-C15 | D30: ☑ | E30: 215577 | F30: ☑ | G30: ☑ | I30: 46224 | J30: =IF($C30="","",LEFT($C30,1)&TEXT(VALUE(MID($C30,2,IFERROR(FIND("-",$C30),LEN($C30)+1)-2)),"000")) -> C009
A31: 212782 | B31: 404019 10005248 | C31: C16-C38 | D31: ☑ | E31: 213680 | F31: ☑ | G31: ☑ | I31: 46224 | J31: =IF($C31="","",LEFT($C31,1)&TEXT(VALUE(MID($C31,2,IFERROR(FIND("-",$C31),LEN($C31)+1)-2)),"000")) -> C016
A32: 213251 | B32: 404026 10005416 | C32: C52-C56 | D32: ☑ | E32: 213680 | F32: ☑ | G32: ☑ | I32: 46224 | J32: =IF($C32="","",LEFT($C32,1)&TEXT(VALUE(MID($C32,2,IFERROR(FIND("-",$C32),LEN($C32)+1)-2)),"000")) -> C052
A33: 213250 | B33: 404021 10005419 | C33: C67-C75 | D33: ☑ | E33: 213680 | F33: ☑ | G33: ☑ | I33: 46224 | J33: =IF($C33="","",LEFT($C33,1)&TEXT(VALUE(MID($C33,2,IFERROR(FIND("-",$C33),LEN($C33)+1)-2)),"000")) -> C067
A34: 207770 | B34: 304022 | C34: E1-E4 | D34: ☑ | E34: Box 9 | F34: ☑ | G34: ☐ | H34: driver # not on box | J34: =IF($C34="","",LEFT($C34,1)&TEXT(VALUE(MID($C34,2,IFERROR(FIND("-",$C34),LEN($C34)+1)-2)),"000")) -> E001
A35: 204951 | B35: 302884 | C35: E5-E9 | D35: ☑ | E35: 203149 | F35: ☑ | G35: ☐ | H35: blue driver box | J35: =IF($C35="","",LEFT($C35,1)&TEXT(VALUE(MID($C35,2,IFERROR(FIND("-",$C35),LEN($C35)+1)-2)),"000")) -> E005
A36: 206808 | B36: 302887 | C36: E10-E11 | D36: ☑ | F36: ☑ | G36: ☑ | H36: ignore for now | I36: 46224 | J36: =IF($C36="","",LEFT($C36,1)&TEXT(VALUE(MID($C36,2,IFERROR(FIND("-",$C36),LEN($C36)+1)-2)),"000")) -> E010
A37: 209175 | B37: 304156 | C37: E12-E15 | D37: ☑ | E37: Box 2 | F37: ☑ | G37: ☐ | H37: driver # not on box | J37: =IF($C37="","",LEFT($C37,1)&TEXT(VALUE(MID($C37,2,IFERROR(FIND("-",$C37),LEN($C37)+1)-2)),"000")) -> E012
A38: 10009530 | B38: 10008496 | C38: E16-E18 | D38: ☑ | E38: 203149 | F38: ☑ | G38: ☐ | H38: blue driver box | J38: =IF($C38="","",LEFT($C38,1)&TEXT(VALUE(MID($C38,2,IFERROR(FIND("-",$C38),LEN($C38)+1)-2)),"000")) -> E016
A39: 10009529 | B39: 10004897 | C39: E19-E21 | D39: ☑ | E39: 203149 | F39: ☑ | G39: ☐ | H39: blue driver box | J39: =IF($C39="","",LEFT($C39,1)&TEXT(VALUE(MID($C39,2,IFERROR(FIND("-",$C39),LEN($C39)+1)-2)),"000")) -> E019
A40: 208519 | B40: 304137 | C40: E22-E26 | D40: ☑ | E40: 203149 | F40: ☑ | G40: ☐ | H40: blue driver box | J40: =IF($C40="","",LEFT($C40,1)&TEXT(VALUE(MID($C40,2,IFERROR(FIND("-",$C40),LEN($C40)+1)-2)),"000")) -> E022
...

Sheet Box Tracker
A1: Box Number | B1: Associated Part Numbers | C1: Driver Part Number(s) | D1: Driver Documentation in Agile? | E1: Notes | F1: Date Complete
A2: Box 1 | B2: 304134 304371 10001073 | D2: ☐
A3: Box 2 | B3: 304761 405378 403262 404380 403263 404381 404900 304265 403260 304156 | D3: ☐
A4: Box 3 | B4: 10002940 | D4: ☐
A5: Box 4 | B5: 304261 304262 304290 | D5: ☐
A6: Box 5 | B6: 304122 304124 304125 304126 304139 304233 304386 304217 304568 304674 304123 402981 | D6: ☐
A7: Box 6 | B7: 402980 | D7: ☐
A8: Box 7 | B8: 304314 | D8: ☐
A9: Box 8 | B9: 404309 404310 | D9: ☐
A10: Box 9 | B10: 304022 | D10: ☐
A11: Box 10 | B11: 302934 | D11: ☐

Sheet Summary
A1: Driver Board Agile Documentation Verification
A2: One row per inventory-sheet entry. Tooling and driver documentation are tracked separately.
A4: Cabinet | B4: Entries | C4: Tooling Docs in Agile | D4: Tooling % | E4: Driver Docs in Agile | F4: Driver %
A5: A | B5: =SUMPRODUCT(--(LEFT(Tracker!$C$2:$C$1000,1)="A")) -> 5 | C5: =SUMPRODUCT(--(LEFT(Tracker!$C$2:$C$1000,1)="A"),--(Tracker!$F$2:$F$1000="☑")) -> 5 | D5: =IF(B5=0,0,C5/B5) -> 1 | E5: =SUMPRODUCT(--(LEFT(Tracker!$C$2:$C$1000,1)="A"),--(Tracker!$G$2:$G$1000="☑")) -> 0 | F5: =IF(B5=0,0,E5/B5) -> 0
A6: B | B6: =SUMPRODUCT(--(LEFT(Tracker!$C$2:$C$1000,1)="B")) -> 21 | C6: =SUMPRODUCT(--(LEFT(Tracker!$C$2:$C$1000,1)="B"),--(Tracker!$F$2:$F$1000="☑")) -> 21 | D6: =IF(B6=0,0,C6/B6) -> 1 | E6: =SUMPRODUCT(--(LEFT(Tracker!$C$2:$C$1000,1)="B"),--(Tracker!$G$2:$G$1000="☑")) -> 4 | F6: =IF(B6=0,0,E6/B6) -> 0.19047619
A7: C | B7: =SUMPRODUCT(--(LEFT(Tracker!$C$2:$C$1000,1)="C")) -> 6 | C7: =SUMPRODUCT(--(LEFT(Tracker!$C$2:$C$1000,1)="C"),--(Tracker!$F$2:$F$1000="☑")) -> 6 | D7: =IF(B7=0,0,C7/B7) -> 1 | E7: =SUMPRODUCT(--(LEFT(Tracker!$C$2:$C$1000,1)="C"),--(Tracker!$G$2:$G$1000="☑")) -> 5 | F7: =IF(B7=0,0,E7/B7) -> 0.83333333
A8: E | B8: =SUMPRODUCT(--(LEFT(Tracker!$C$2:$C$1000,1)="E")) -> 14 | C8: =SUMPRODUCT(--(LEFT(Tracker!$C$2:$C$1000,1)="E"),--(Tracker!$F$2:$F$1000="☑")) -> 14 | D8: =IF(B8=0,0,C8/B8) -> 1 | E8: =SUMPRODUCT(--(LEFT(Tracker!$C$2:$C$1000,1)="E"),--(Tracker!$G$2:$G$1000="☑")) -> 4 | F8: =IF(B8=0,0,E8/B8) -> 0.28571429
A9: G | B9: =SUMPRODUCT(--(LEFT(Tracker!$C$2:$C$1000,1)="G")) -> 1 | C9: =SUMPRODUCT(--(LEFT(Tracker!$C$2:$C$1000,1)="G"),--(Tracker!$F$2:$F$1000="☑")) -> 1 | D9: =IF(B9=0,0,C9/B9) -> 1 | E9: =SUMPRODUCT(--(LEFT(Tracker!$C$2:$C$1000,1)="G"),--(Tracker!$G$2:$G$1000="☑")) -> 1 | F9: =IF(B9=0,0,E9/B9) -> 1
A10: Total | B10: =SUM(B5:B9) -> 47 | C10: =SUM(C5:C9) -> 47 | D10: =IF(B10=0,0,C10/B10) -> 1 | E10: =SUM(E5:E9) -> 14 | F10: =IF(B10=0,0,E10/B10) -> 0.29787234
A13: How to Use
A14: 1. Checkboxes: tap the cell and pick ☑ (checked) or ☐ (unchecked) from the dropdown. Blank counts as unchecked.
A15: 2. If the driver is found, check 'Driver Found?' and enter its number in Driver Number.
A16: 3. Check 'Tooling Documentation in Agile?' and 'Driver Documentation in Agile?' as you verify each in Agile.
A17: The row turns green when BOTH are checked, and the Summary above tracks each one separately.
A18: 4. ADDING AN ENTRY: type it in the first empty row under the table (Location can be a single slot like B50 or a range like B50-B52).
A19: Sort Key fills in automatically; click its header arrow and Sort A to Z to slot the entry into the correct position.
A20: If a multi-line row looks clipped after sorting, select the rows and use Home > Format > AutoFit Row Height.
A21: 5. Notes is free text. Date Complete uses mm/dd/yyyy.
A23: Example entry (format only - not real data; Sort Key fills itself):
A24: Tooling Number | B24: Part Number | C24: Location | D24: Driver Found? | E24: Driver Number | F24: Tooling Documentation in Agile? | G24: Driver Documentation in Agile? | H24: Notes | I24: Date Complete | J24: Sort Key
A25: 205999 | B25: 301234 301235 | C25: B50-B52 | D25: ☑ | E25: 208001 | F25: ☑ | G25: ☑ | H25: Verified against Agile rev B | I25: 07/20/2026 | J25: B050
