Workbook

Sheet README
A1: PCB COMPONENT VERIFICATION TRACKER v3 — X-Band ESA Subarray/Module
A2: Reconciles Master BOM ↔ PADS Logic (schematic) ↔ PADS Layout (board), verifies footprints and part numbers, and tracks physical inspection.
A4: LEGEND
A5: Light yellow cells = YOU paste or type data here. All other cells contain formulas — do not overwrite them.
A6: Rows 2–5 of each paste sheet contain EXAMPLE values showing the expected format. CLEAR their contents before pasting real data. Clear contents only — never delete entire rows, or the formulas that point at those rows will break.
A7: Always use Paste Special > Values so fills, dropdowns, and text formats are preserved. If your board exceeds the pre-built 3,000 formula rows, select the last formula row and fill it down.
A9: STEP 1 — SOURCE DATA
A10: A) Schematic: run your parser tool on the PADS Logic export. It produces tab-separated rows, no header, one row per physical part (ref des deduplicated and sorted), with exactly these five columns in order: 1 Ref Des, 2 Part Type, 3 PCB Decal, 4 EDU Part Number, 5 FLIGHT Part Number. The part-number columns may be blank for some parts.
A11: B) PADS Layout → File > Export (.asc): check PARTS (+ Expand Attributes: PARTS, and ASSEMBLY VARIANTS if used). In the *PART* section each line reads: RefDes PartType@Decal X Y Orientation ... — the DECAL after the @ is the footprint actually placed. A mirror flag (M) indicates the BOTTOM side.
A12: C) CAM Plus list file: TOP and BOTTOM runs, pin type = ALL, check 'Read part definitions' and 'Read value attributes'. Cleanest source for ref des per side.
A14: STEP 2 — PASTE INTO THIS WORKBOOK
A15: 1. Master BOM: paste your 5 BOM columns into A–E, then fill column F 'Expected Footprint / Package' (0402, QFN24, SOT23, ...) for every line that places on the board. Dashes/underscores/spaces are ignored during matching. Leave F blank for hardware lines with no ref des. Dash ranges in Ref. Des. (C1-C9) are flagged in column H — expand them to full comma lists.
... A32: Dashboard: % Complete = 100%, footprint checks complete, zero unresolved flags, discrepancies closed. Fill the sign-off block.

Sheet Dashboard
A1: PCB COMPONENT VERIFICATION — DASHBOARD
A3: Assembly / Board:
A4: Serial Number:
A5: PCB Rev / BOM Rev:
A6: Verified By:
A7: Sign-off Date:
A9: VERIFICATION PROGRESS
A10: Total parts placed (from Layout) | B10: =COUNTIF('4. Tracker'!$A$2:$A$3001,"?*") -> 4 | C10: One row per ref des on the board
A11: Top side | B11: =COUNTIF('4. Tracker'!$B$2:$B$3001,"Top") -> 3
A12: Bottom side | B12: =COUNTIF('4. Tracker'!$B$2:$B$3001,"Bottom") -> 1
A13: Pass | B13: =COUNTIF('4. Tracker'!$U$2:$U$3001,"Pass") -> 1
A14: Fail — all | B14: =COUNTIF('4. Tracker'!$U$2:$U$3001,"Fail*") -> 1
A15: Fail — Missing | B15: =COUNTIF('4. Tracker'!$U$2:$U$3001,"Fail - Missing") -> 1
A16: Fail — Wrong Part | B16: =COUNTIF('4. Tracker'!$U$2:$U$3001,"Fail - Wrong Part") -> 0
A17: Fail — Orientation | B17: =COUNTIF('4. Tracker'!$U$2:$U$3001,"Fail - Orientation") -> 0
A18: Fail — Damaged | B18: =COUNTIF('4. Tracker'!$U$2:$U$3001,"Fail - Damaged") -> 0
A19: DNP — verified absent | B19: =COUNTIF('4. Tracker'!$U$2:$U$3001,"DNP*") -> 0
A20: N/A | B20: =COUNTIF('4. Tracker'!$U$2:$U$3001,"N/A") -> 0
A21: Checked (Pass + Fail + DNP + N/A) | B21: =$B$13+$B$14+$B$19+$B$20 -> 2
A22: Remaining (not yet checked) | B22: =$B$10-$B$21 -> 2
A23: % Complete | B23: =IF($B$10=0,0,$B$21/$B$10) -> 0.5
A25: FOOTPRINT VERIFICATION (per BOM item — sheet 6)
A26: BOM items total | B26: =COUNTA('1. Master BOM'!$A$2:$A$400) -> 4
A27: Footprint verified — Pass | B27: =COUNTIF('6. Footprint Check'!$I$2:$I$400,"Pass") -> 1
A28: Footprint verified — Fail | B28: =COUNTIF('6. Footprint Check'!$I$2:$I$400,"Fail") -> 0
A29: N/A — not placed | B29: =COUNTIF('6. Footprint Check'!$I$2:$I$400,"N/A*") -> 0 | C29: Hardware / DNP-only items
A30: Footprint checks remaining | B30: =$B$26-$B$27-$B$28-$B$29 -> 3
A31: Items placed with MIXED decals | B31: =COUNTIF('6. Footprint Check'!$G$2:$G$400,"MIXED") -> 0 | C31: Same BOM item, more than one footprint — review
A32: Auto-screen flags (item level) | B32: =COUNTIF('6. Footprint Check'!$H$2:$H$400,"CHECK") -> 0 | C32: Decal name lacks expected package string — verify by eye
A34: DATA RECONCILIATION FLAGS — must be 0 (or dispositioned) before physical check
A35: Placed parts NOT IN SCHEMATIC | B35: =COUNTIF('4. Tracker'!$H$2:$H$3001,"NOT IN SCHEMATIC") -> 0 | C35: On the board but not in Logic — investigate
A36: Part type MISMATCH (Logic vs Layout) | B36: =COUNTIF('4. Tracker'!$I$2:$I$3001,"MISMATCH") -> 0 | C36: Same ref des, different part type
A37: Decal MISMATCH (Sch vs Layout) | B37: =COUNTIF('4. Tracker'!$J$2:$J$3001,"MISMATCH") -> 0 | C37: Schematic PCB decal differs from decal placed on board
A38: PN MISMATCH (Sch vs BOM) | B38: =COUNTIF('4. Tracker'!$P$2:$P$3001,"MISMATCH") -> 0 | C38: Schematic EDU Part Number differs from BOM EDU Mfr Number
A39: No schematic decal (info) | B39: =COUNTIF('4. Tracker'!$J$2:$J$3001,"NO SCH DECAL") -> 0 | C39: Blank PCB Decal in parser output — not an error
A40: No schematic PN (info) | B40: =COUNTIF('4. Tracker'!$P$2:$P$3001,"NO SCH PN") -> 1 | C40: Blank EDU Part Number in parser output — not an error
A41: Placed parts NOT IN BOM | B41: =COUNTIF('4. Tracker'!$M$2:$M$3001,"NOT IN BOM") -> 0 | C41: Check for unexpanded ranges in BOM ref-des lists first
A42: Ref des on MULTIPLE BOM LINES | B42: =COUNTIF('4. Tracker'!$M$2:$M$3001,"MULTIPLE BOM LINES") -> 0 | C42: Same ref des claimed by two BOM items
A43: Tracker rows flagged REVIEW | B43: =COUNTIF('4. Tracker'!$T$2:$T$3001,"REVIEW") -> 0 | C43: Union of the MISMATCH / not-found flags above
A44: Tracker footprint auto flags (per ref des) | B44: =COUNTIF('4. Tracker'!$S$2:$S$3001,"CHECK") -> 0 | C44: Screening only — disposition on sheet 6
...

Sheet 1. Master BOM
A1: Item | B1: EDU Mfr Number | C1: Single Unit Qty | D1: Ref. Des. | E1: Description | F1: Expected Footprint / Package | G1: # Ref Des Listed | H1: Qty Check | I1: Placed On Board | J1: Board Qty Check
A2: 1 | B2: EDU-100123-001 | C2: 2 | D2: C1, C2 | E2: CAP, CER, 100pF, 5%, 50V, 0402 | F2: 0402 | G2: =IF(TRIM($D2)="","",LEN(TRIM($D2))-LEN(SUBSTITUTE(TRIM($D2),",",""))+1) -> 2 | H2: =IF(OR(TRIM($D2)="",$C2=""),"",IF(ISNUMBER(SEARCH("-",$D2)),"RANGE - EXPAND",IF($G2=$C2,"OK","QTY MISMATCH"))) -> OK | I2: =IF($A2="","",COUNTIF('4. Tracker'!$N$2:$N$3001,$A2)) -> 2 | J2: =IF(OR($A2="",$C2=""),"",IF(TRIM($D2)="","MANUAL - NO REFDES",IF($I2=$C2,"OK",IF($I2<$C2,"SHORT ("&$I2&" of "&$C2&")","OVER ("&$I2&" of "&$C2&")")))) -> OK
A3: 2 | B3: EDU-100456-001 | C3: 1 | D3: U1 | E3: MMIC, GaN PA, X-BAND, QFN-24 | F3: QFN24 | G3: =IF(TRIM($D3)="","",LEN(TRIM($D3))-LEN(SUBSTITUTE(TRIM($D3),",",""))+1) -> 1 | H3: =IF(OR(TRIM($D3)="",$C3=""),"",IF(ISNUMBER(SEARCH("-",$D3)),"RANGE - EXPAND",IF($G3=$C3,"OK","QTY MISMATCH"))) -> OK | I3: =IF($A3="","",COUNTIF('4. Tracker'!$N$2:$N$3001,$A3)) -> 1 | J3: =IF(OR($A3="",$C3=""),"",IF(TRIM($D3)="","MANUAL - NO REFDES",IF($I3=$C3,"OK",IF($I3<$C3,"SHORT ("&$I3&" of "&$C3&")","OVER ("&$I3&" of "&$C3&")")))) -> OK
A4: 3 | B4: EDU-100789-001 | C4: 1 | D4: J1 | E4: CONNECTOR, RF, SMPM, PCB MOUNT | F4: SMPM | G4: =IF(TRIM($D4)="","",LEN(TRIM($D4))-LEN(SUBSTITUTE(TRIM($D4),",",""))+1) -> 1 | H4: =IF(OR(TRIM($D4)="",$C4=""),"",IF(ISNUMBER(SEARCH("-",$D4)),"RANGE - EXPAND",IF($G4=$C4,"OK","QTY MISMATCH"))) -> OK | I4: =IF($A4="","",COUNTIF('4. Tracker'!$N$2:$N$3001,$A4)) -> 1 | J4: =IF(OR($A4="",$C4=""),"",IF(TRIM($D4)="","MANUAL - NO REFDES",IF($I4=$C4,"OK",IF($I4<$C4,"SHORT ("&$I4&" of "&$C4&")","OVER ("&$I4&" of "&$C4&")")))) -> OK
A5: 4 | B5: EDU-100900-001 | C5: 4 | E5: SCREW, M2 X 4MM, SST, PHILLIPS | G5: =IF(TRIM($D5)="","",LEN(TRIM($D5))-LEN(SUBSTITUTE(TRIM($D5),",",""))+1) | H5: =IF(OR(TRIM($D5)="",$C5=""),"",IF(ISNUMBER(SEARCH("-",$D5)),"RANGE - EXPAND",IF($G5=$C5,"OK","QTY MISMATCH"))) | I5: =IF($A5="","",COUNTIF('4. Tracker'!$N$2:$N$3001,$A5)) -> 0 | J5: =IF(OR($A5="",$C5=""),"",IF(TRIM($D5)="","MANUAL - NO REFDES",IF($I5=$C5,"OK",IF($I5<$C5,"SHORT ("&$I5&" of "&$C5&")","OVER ("&$I5&" of "&$C5&")")))) -> MANUAL - NO REFDES
G6: =IF(TRIM($D6)="","",LEN(TRIM($D6))-LEN(SUBSTITUTE(TRIM($D6),",",""))+1) | H6: =IF(OR(TRIM($D6)="",$C6=""),"",IF(ISNUMBER(SEARCH("-",$D6)),"RANGE - EXPAND",IF($G6=$C6,"OK","QTY MISMATCH"))) | I6: =IF($A6="","",COUNTIF('4. Tracker'!$N$2:$N$3001,$A6)) | J6: =IF(OR($A6="",$C6=""),"",IF(TRIM($D6)="","MANUAL - NO REFDES",IF($I6=$C6,"OK",IF($I6<$C6,"SHORT ("&$I6&" of "&$C6&")","OVER ("&$I6&" of "&$C6&")"))))
G7: =IF(TRIM($D7)="","",LEN(TRIM($D7))-LEN(SUBSTITUTE(TRIM($D7),",",""))+1) | H7: =IF(OR(TRIM($D7)="",$C7=""),"",IF(ISNUMBER(SEARCH("-",$D7)),"RANGE - EXPAND",IF($G7=$C7,"OK","QTY MISMATCH"))) | I7: =IF($A7="","",COUNTIF('4. Tracker'!$N$2:$N$3001,$A7)) | J7: =IF(OR($A7="",$C7=""),"",IF(TRIM($D7)="","MANUAL - NO REFDES",IF($I7=$C7,"OK",IF($I7<$C7,"SHORT ("&$I7&" of "&$C7&")","OVER ("&$I7&" of "&$C7&")"))))
G8: =IF(TRIM($D8)="","",LEN(TRIM($D8))-LEN(SUBSTITUTE(TRIM($D8),",",""))+1) | H8: =IF(OR(TRIM($D8)="",$C8=""),"",IF(ISNUMBER(SEARCH("-",$D8)),"RANGE - EXPAND",IF($G8=$C8,"OK","QTY MISMATCH"))) | I8: =IF($A8="","",COUNTIF('4. Tracker'!$N$2:$N$3001,$A8)) | J8: =IF(OR($A8="",$C8=""),"",IF(TRIM($D8)="","MANUAL - NO REFDES",IF($I8=$C8,"OK",IF($I8<$C8,"SHORT ("&$I8&" of "&$C8&")","OVER ("&$I8&" of "&$C8&")"))))
G9: =IF(TRIM($D9)="","",LEN(TRIM($D9))-LEN(SUBSTITUTE(TRIM($D9),",",""))+1) | H9: =IF(OR(TRIM($D9)="",$C9=""),"",IF(ISNUMBER(SEARCH("-",$D9)),"RANGE - EXPAND",IF($G9=$C9,"OK","QTY MISMATCH"))) | I9: =IF($A9="","",COUNTIF('4. Tracker'!$N$2:$N$3001,$A9)) | J9: =IF(OR($A9="",$C9=""),"",IF(TRIM($D9)="","MANUAL - NO REFDES",IF($I9=$C9,"OK",IF($I9<$C9,"SHORT ("&$I9&" of "&$C9&")","OVER ("&$I9&" of "&$C9&")"))))
G10: =IF(TRIM($D10)="","",LEN(TRIM($D10))-LEN(SUBSTITUTE(TRIM($D10),",",""))+1) | H10: =IF(OR(TRIM($D10)="",$C10=""),"",IF(ISNUMBER(SEARCH("-",$D10)),"RANGE - EXPAND",IF($G10=$C10,"OK","QTY MISMATCH"))) | I10: =IF($A10="","",COUNTIF('4. Tracker'!$N$2:$N$3001,$A10)) | J10: =IF(OR($A10="",$C10=""),"",IF(TRIM($D10)="","MANUAL - NO REFDES",IF($I10=$C10,"OK",IF($I10<$C10,"SHORT ("&$I10&" of "&$C10&")","OVER ("&$I10&" of "&$C10&")"))))
G11: =IF(TRIM($D11)="","",LEN(TRIM($D11))-LEN(SUBSTITUTE(TRIM($D11),",",""))+1) | H11: =IF(OR(TRIM($D11)="",$C11=""),"",IF(ISNUMBER(SEARCH("-",$D11)),"RANGE - EXPAND",IF($G11=$C11,"OK","QTY MISMATCH"))) | I11: =IF($A11="","",COUNTIF('4. Tracker'!$N$2:$N$3001,$A11)) | J11: =IF(OR($A11="",$C11=""),"",IF(TRIM($D11)="","MANUAL - NO REFDES",IF($I11=$C11,"OK",IF($I11<$C11,"SHORT ("&$I11&" of "&$C11&")","OVER ("&$I11&" of "&$C11&")"))))
G12: =IF(TRIM($D12)="","",LEN(TRIM($D12))-LEN(SUBSTITUTE(TRIM($D12),",",""))+1) | H12: =IF(OR(TRIM($D12)="",$C12=""),"",IF(ISNUMBER(SEARCH("-",$D12)),"RANGE - EXPAND",IF($G12=$C12,"OK","QTY MISMATCH"))) | I12: =IF($A12="","",COUNTIF('4. Tracker'!$N$2:$N$3001,$A12)) | J12: =IF(OR($A12="",$C12=""),"",IF(TRIM($D12)="","MANUAL - NO REFDES",IF($I12=$C12,"OK",IF($I12<$C12,"SHORT ("&$I12&" of "&$C12&")","OVER ("&$I12&" of "&$C12&")"))))
G13: =IF(TRIM($D13)="","",LEN(TRIM($D13))-LEN(SUBSTITUTE(TRIM($D13),",",""))+1) | H13: =IF(OR(TRIM($D13)="",$C13=""),"",IF(ISNUMBER(SEARCH("-",$D13)),"RANGE - EXPAND",IF($G13=$C13,"OK","QTY MISMATCH"))) | I13: =IF($A13="","",COUNTIF('4. Tracker'!$N$2:$N$3001,$A13)) | J13: =IF(OR($A13="",$C13=""),"",IF(TRIM($D13)="","MANUAL - NO REFDES",IF($I13=$C13,"OK",IF($I13<$C13,"SHORT ("&$I13&" of "&$C13&")","OVER ("&$I13&" of "&$C13&")"))))
G14: =IF(TRIM($D14)="","",LEN(TRIM($D14))-LEN(SUBSTITUTE(TRIM($D14),",",""))+1) | H14: =IF(OR(TRIM($D14)="",$C14=""),"",IF(ISNUMBER(SEARCH("-",$D14)),"RANGE - EXPAND",IF($G14=$C14,"OK","QTY MISMATCH"))) | I14: =IF($A14="","",COUNTIF('4. Tracker'!$N$2:$N$3001,$A14)) | J14: =IF(OR($A14="",$C14=""),"",IF(TRIM($D14)="","MANUAL - NO REFDES",IF($I14=$C14,"OK",IF($I14<$C14,"SHORT ("&$I14&" of "&$C14&")","OVER ("&$I14&" of "&$C14&")"))))
G15: =IF(TRIM($D15)="","",LEN(TRIM($D15))-LEN(SUBSTITUTE(TRIM($D15),",",""))+1) | H15: =IF(OR(TRIM($D15)="",$C15=""),"",IF(ISNUMBER(SEARCH("-",$D15)),"RANGE - EXPAND",IF($G15=$C15,"OK","QTY MISMATCH"))) | I15: =IF($A15="","",COUNTIF('4. Tracker'!$N$2:$N$3001,$A15)) | J15: =IF(OR($A15="",$C15=""),"",IF(TRIM($D15)="","MANUAL - NO REFDES",IF($I15=$C15,"OK",IF($I15<$C15,"SHORT ("&$I15&" of "&$C15&")","OVER ("&$I15&" of "&$C15&")"))))
G16: =IF(TRIM($D16)="","",LEN(TRIM($D16))-LEN(SUBSTITUTE(TRIM($D16),",",""))+1) | H16: =IF(OR(TRIM($D16)="",$C16=""),"",IF(ISNUMBER(SEARCH("-",$D16)),"RANGE - EXPAND",IF($G16=$C16,"OK","QTY MISMATCH"))) | I16: =IF($A16="","",COUNTIF('4. Tracker'!$N$2:$N$3001,$A16)) | J16: =IF(OR($A16="",$C16=""),"",IF(TRIM($D16)="","MANUAL - NO REFDES",IF($I16=$C16,"OK",IF($I16<$C16,"SHORT ("&$I16&" of "&$C16&")","OVER ("&$I16&" of "&$C16&")"))))
G17: =IF(TRIM($D17)="","",LEN(TRIM($D17))-LEN(SUBSTITUTE(TRIM($D17),",",""))+1) | H17: =IF(OR(TRIM($D17)="",$C17=""),"",IF(ISNUMBER(SEARCH("-",$D17)),"RANGE - EXPAND",IF($G17=$C17,"OK","QTY MISMATCH"))) | I17: =IF($A17="","",COUNTIF('4. Tracker'!$N$2:$N$3001,$A17)) | J17: =IF(OR($A17="",$C17=""),"",IF(TRIM($D17)="","MANUAL - NO REFDES",IF($I17=$C17,"OK",IF($I17<$C17,"SHORT ("&$I17&" of "&$C17&")","OVER ("&$I17&" of "&$C17&")"))))
... G400: =IF(TRIM($D400)="","",LEN(TRIM($D400))-LEN(SUBSTITUTE(TRIM($D400),",",""))+1) | H400: =IF(OR(TRIM($D400)="",$C400=""),"",IF(ISNUMBER(SEARCH("-",$D400)),"RANGE - EXPAND",IF($G400=$C400,"OK","QTY MISMATCH"))) | I400: =IF($A400="","",COUNTIF('4. Tracker'!$N$2:$N$3001,$A400)) | J400: =IF(OR($A400="",$C400=""),"",IF(TRIM($D400)="","MANUAL - NO REFDES",IF($I400=$C400,"OK",IF($I400<$C400,"SHORT ("&$I400&" of "&$C400&")","OVER ("&$I400&" of "&$C400&")"))))

Sheet 2. Schematic Parts
A1: Ref Des | B1: Part Type | C1: PCB Decal | D1: EDU Part Number | E1: FLIGHT Part Number | F1: Duplicate? | G1: On Board?
A2: C1 | B2: CAP100PF0402 | C2: CAP0402 | D2: EDU-100123-001 | E2: FLT-100123-001 | F2: =IF($A2="","",IF(COUNTIF($A$2:$A$3001,$A2)>1,"DUPLICATE","")) | G2: =IF($A2="","",IF(COUNTIF('3. Layout Parts'!$A$2:$A$3001,$A2)=0,"NOT ON BOARD","OK")) -> OK
A3: C2 | B3: CAP100PF0402 | C3: CAP0402 | D3: EDU-100123-001 | E3: FLT-100123-001 | F3: =IF($A3="","",IF(COUNTIF($A$2:$A$3001,$A3)>1,"DUPLICATE","")) | G3: =IF($A3="","",IF(COUNTIF('3. Layout Parts'!$A$2:$A$3001,$A3)=0,"NOT ON BOARD","OK")) -> OK
A4: U1 | B4: MMIC_PA_XB | C4: QFN24_4X4 | D4: EDU-100456-001 | E4: FLT-100456-001 | F4: =IF($A4="","",IF(COUNTIF($A$2:$A$3001,$A4)>1,"DUPLICATE","")) | G4: =IF($A4="","",IF(COUNTIF('3. Layout Parts'!$A$2:$A$3001,$A4)=0,"NOT ON BOARD","OK")) -> OK
A5: J1 | B5: SMPM_CONN | C5: SMPM_SMT | F5: =IF($A5="","",IF(COUNTIF($A$2:$A$3001,$A5)>1,"DUPLICATE","")) | G5: =IF($A5="","",IF(COUNTIF('3. Layout Parts'!$A$2:$A$3001,$A5)=0,"NOT ON BOARD","OK")) -> OK
F6: =IF($A6="","",IF(COUNTIF($A$2:$A$3001,$A6)>1,"DUPLICATE","")) | G6: =IF($A6="","",IF(COUNTIF('3. Layout Parts'!$A$2:$A$3001,$A6)=0,"NOT ON BOARD","OK"))
F7: =IF($A7="","",IF(COUNTIF($A$2:$A$3001,$A7)>1,"DUPLICATE","")) | G7: =IF($A7="","",IF(COUNTIF('3. Layout Parts'!$A$2:$A$3001,$A7)=0,"NOT ON BOARD","OK"))
F8: =IF($A8="","",IF(COUNTIF($A$2:$A$3001,$A8)>1,"DUPLICATE","")) | G8: =IF($A8="","",IF(COUNTIF('3. Layout Parts'!$A$2:$A$3001,$A8)=0,"NOT ON BOARD","OK"))
F9: =IF($A9="","",IF(COUNTIF($A$2:$A$3001,$A9)>1,"DUPLICATE","")) | G9: =IF($A9="","",IF(COUNTIF('3. Layout Parts'!$A$2:$A$3001,$A9)=0,"NOT ON BOARD","OK"))
F10: =IF($A10="","",IF(COUNTIF($A$2:$A$3001,$A10)>1,"DUPLICATE","")) | G10: =IF($A10="","",IF(COUNTIF('3. Layout Parts'!$A$2:$A$3001,$A10)=0,"NOT ON BOARD","OK"))
F11: =IF($A11="","",IF(COUNTIF($A$2:$A$3001,$A11)>1,"DUPLICATE","")) | G11: =IF($A11="","",IF(COUNTIF('3. Layout Parts'!$A$2:$A$3001,$A11)=0,"NOT ON BOARD","OK"))
F12: =IF($A12="","",IF(COUNTIF($A$2:$A$3001,$A12)>1,"DUPLICATE","")) | G12: =IF($A12="","",IF(COUNTIF('3. Layout Parts'!$A$2:$A$3001,$A12)=0,"NOT ON BOARD","OK"))
F13: =IF($A13="","",IF(COUNTIF($A$2:$A$3001,$A13)>1,"DUPLICATE","")) | G13: =IF($A13="","",IF(COUNTIF('3. Layout Parts'!$A$2:$A$3001,$A13)=0,"NOT ON BOARD","OK"))
F14: =IF($A14="","",IF(COUNTIF($A$2:$A$3001,$A14)>1,"DUPLICATE","")) | G14: =IF($A14="","",IF(COUNTIF('3. Layout Parts'!$A$2:$A$3001,$A14)=0,"NOT ON BOARD","OK"))
F15: =IF($A15="","",IF(COUNTIF($A$2:$A$3001,$A15)>1,"DUPLICATE","")) | G15: =IF($A15="","",IF(COUNTIF('3. Layout Parts'!$A$2:$A$3001,$A15)=0,"NOT ON BOARD","OK"))
F16: =IF($A16="","",IF(COUNTIF($A$2:$A$3001,$A16)>1,"DUPLICATE","")) | G16: =IF($A16="","",IF(COUNTIF('3. Layout Parts'!$A$2:$A$3001,$A16)=0,"NOT ON BOARD","OK"))
F17: =IF($A17="","",IF(COUNTIF($A$2:$A$3001,$A17)>1,"DUPLICATE","")) | G17: =IF($A17="","",IF(COUNTIF('3. Layout Parts'!$A$2:$A$3001,$A17)=0,"NOT ON BOARD","OK"))
... F3001: =IF($A3001="","",IF(COUNTIF($A$2:$A$3001,$A3001)>1,"DUPLICATE","")) | G3001: =IF($A3001="","",IF(COUNTIF('3. Layout Parts'!$A$2:$A$3001,$A3001)=0,"NOT ON BOARD","OK"))

Sheet 3. Layout Parts
A1: Ref Des | B1: Part Type | C1: Decal / Footprint | D1: Side (Top/Bottom) | E1: X | F1: Y | G1: Rotation | H1: Duplicate?
A2: C1 | B2: CAP100PF0402 | C2: CAP0402 | D2: Top | E2: 1250 | F2: 800 | G2: 90 | H2: =IF($A2="","",IF(COUNTIF($A$2:$A$3001,$A2)>1,"DUPLICATE",""))
A3: C2 | B3: CAP100PF0402 | C3: CAP0402 | D3: Top | E3: 1310 | F3: 800 | G3: 270 | H3: =IF($A3="","",IF(COUNTIF($A$2:$A$3001,$A3)>1,"DUPLICATE",""))
A4: U1 | B4: MMIC_PA_XB | C4: QFN24_4X4 | D4: Top | E4: 1500 | F4: 950 | G4: 0 | H4: =IF($A4="","",IF(COUNTIF($A$2:$A$3001,$A4)>1,"DUPLICATE",""))
A5: J1 | B5: SMPM_CONN | C5: SMPM_SMT | D5: Bottom | E5: 200 | F5: 150 | G5: 180 | H5: =IF($A5="","",IF(COUNTIF($A$2:$A$3001,$A5)>1,"DUPLICATE",""))
H6: =IF($A6="","",IF(COUNTIF($A$2:$A$3001,$A6)>1,"DUPLICATE",""))
H7: =IF($A7="","",IF(COUNTIF($A$2:$A$3001,$A7)>1,"DUPLICATE",""))
H8: =IF($A8="","",IF(COUNTIF($A$2:$A$3001,$A8)>1,"DUPLICATE",""))
H9: =IF($A9="","",IF(COUNTIF($A$2:$A$3001,$A9)>1,"DUPLICATE",""))
H10: =IF($A10="","",IF(COUNTIF($A$2:$A$3001,$A10)>1,"DUPLICATE",""))
H11: =IF($A11="","",IF(COUNTIF($A$2:$A$3001,$A11)>1,"DUPLICATE",""))
H12: =IF($A12="","",IF(COUNTIF($A$2:$A$3001,$A12)>1,"DUPLICATE",""))
H13: =IF($A13="","",IF(COUNTIF($A$2:$A$3001,$A13)>1,"DUPLICATE",""))
H14: =IF($A14="","",IF(COUNTIF($A$2:$A$3001,$A14)>1,"DUPLICATE",""))
H15: =IF($A15="","",IF(COUNTIF($A$2:$A$3001,$A15)>1,"DUPLICATE",""))
H16: =IF($A16="","",IF(COUNTIF($A$2:$A$3001,$A16)>1,"DUPLICATE",""))
H17: =IF($A17="","",IF(COUNTIF($A$2:$A$3001,$A17)>1,"DUPLICATE",""))
... H3001: =IF($A3001="","",IF(COUNTIF($A$2:$A$3001,$A3001)>1,"DUPLICATE",""))

Sheet 4. Tracker
A1: Ref Des | B1: Side | C1: Part Type (Layout) | D1: Decal (Layout) | E1: Part Type (Schematic) | F1: Decal (Schematic) | G1: EDU PN (Schematic) | H1: In Schematic? | I1: Type Match? | J1: Decal Match (Sch vs Layout)? | K1: BOM Hits (helper) | L1: BOM Row (helper) | M1: In BOM? | N1: BOM Item | O1: EDU Mfr Number (BOM) | P1: PN Match (Sch vs BOM)? | Q1: Description | R1: Expected Footprint (BOM) | S1: Footprint Check (auto) | T1: Data Check | U1: Physical Status | V1: Checked By | W1: Date Checked | X1: Notes
A2: =IF('3. Layout Parts'!$A2="","",TRIM('3. Layout Parts'!$A2)) -> C1 | B2: =IF($A2="","",'3. Layout Parts'!$D2) -> Top | C2: =IF($A2="","",'3. Layout Parts'!$B2) -> CAP100PF0402 | D2: =IF($A2="","",'3. Layout Parts'!$C2) -> CAP0402 | E2: =IF($A2="","",IFERROR(INDEX('2. Schematic Parts'!$B$2:$B$3001,MATCH($A2,'2. Schematic Parts'!$A$2:$A$3001,0)),"NOT FOUND")) -> CAP100PF0402 | F2: =IF($A2="","",IFERROR(INDEX('2. Schematic Parts'!$C$2:$C$3001,MATCH($A2,'2. Schematic Parts'!$A$2:$A$3001,0))&"","NOT FOUND")) -> CAP0402 | G2: =IF($A2="","",IFERROR(INDEX('2. Schematic Parts'!$D$2:$D$3001,MATCH($A2,'2. Schematic Parts'!$A$2:$A$3001,0))&"","NOT FOUND")) -> EDU-100123-001 | H2: =IF($A2="","",IF(COUNTIF('2. Schematic Parts'!$A$2:$A$3001,$A2)=0,"NOT IN SCHEMATIC","OK")) -> OK | I2: =IF($A2="","",IF($H2="NOT IN SCHEMATIC","",IF(UPPER(TRIM($C2))=UPPER(TRIM($E2)),"OK","MISMATCH"))) -> OK | J2: =IF($A2="","",IF($H2="NOT IN SCHEMATIC","",IF($F2="","NO SCH DECAL",IF($D2="","",IF(UPPER(TRIM($D2))=UPPER(TRIM($F2)),"OK","MISMATCH"))))) -> OK | K2: =IF($A2="","",SUMPRODUCT(--ISNUMBER(SEARCH(","&TRIM($A2)&",",","&SUBSTITUTE('1. Master BOM'!$D$2:$D$400," ","")&",")))) -> 1 | L2: =IF($A2="","",IF($K2<>1,0,SUMPRODUCT(ISNUMBER(SEARCH(","&TRIM($A2)&",",","&SUBSTITUTE('1. Master BOM'!$D$2:$D$400," ","")&","))*ROW('1. Master BOM'!$D$2:$D$400)))) -> 2 | M2: =IF($A2="","",IF($K2=0,"NOT IN BOM",IF($K2>1,"MULTIPLE BOM LINES","OK"))) -> OK | N2: =IF($A2="","",IF($L2=0,"—",INDEX('1. Master BOM'!$A$1:$A$400,$L2))) -> 1 | O2: =IF($A2="","",IF($L2=0,"—",INDEX('1. Master BOM'!$B$1:$B$400,$L2))) -> EDU-100123-001 | P2: =IF($A2="","",IF(OR($H2="NOT IN SCHEMATIC",$O2="—"),"",IF($G2="","NO SCH PN",IF(UPPER(TRIM($G2))=UPPER(TRIM($O2)),"OK","MISMATCH")))) -> OK | Q2: =IF($A2="","",IF($L2=0,"—",INDEX('1. Master BOM'!$E$1:$E$400,$L2))) -> CAP, CER, 100pF, 5%, 50V, 0402 | R2: =IF($A2="","",IF($L2=0,"—",IF(T(INDEX('1. Master BOM'!$F$1:$F$400,$L2))="","(not set)",INDEX('1. Master BOM'!$F$1:$F$400,$L2)))) -> 0402 | S2: =IF($A2="","",IF(OR($R2="—",$R2="(not set)",$D2=""),"",IF(ISNUMBER(SEARCH(SUBSTITUTE(SUBSTITUTE(SUBSTITUTE($R2,"-",""),"_","")," ",""),SUBSTITUTE(SUBSTITUTE(SUBSTITUTE($D2,"-",""),"_","")," ",""))),"OK","CHECK"))) -> OK | T2: =IF($A2="","",IF(OR($H2="NOT IN SCHEMATIC",$I2="MISMATCH",$J2="MISMATCH",$P2="MISMATCH",$M2<>"OK"),"REVIEW","OK")) -> OK | U2: Pass | V2: AB | W2: 46217 | X2: Example row — clear U:X before use
A3: =IF('3. Layout Parts'!$A3="","",TRIM('3. Layout Parts'!$A3)) -> C2 | B3: =IF($A3="","",'3. Layout Parts'!$D3) -> Top | C3: =IF($A3="","",'3. Layout Parts'!$B3) -> CAP100PF0402 | D3: =IF($A3="","",'3. Layout Parts'!$C3) -> CAP0402 | E3: =IF($A3="","",IFERROR(INDEX('2. Schematic Parts'!$B$2:$B$3001,MATCH($A3,'2. Schematic Parts'!$A$2:$A$3001,0)),"NOT FOUND")) -> CAP100PF0402 | F3: =IF($A3="","",IFERROR(INDEX('2. Schematic Parts'!$C$2:$C$3001,MATCH($A3,'2. Schematic Parts'!$A$2:$A$3001,0))&"","NOT FOUND")) -> CAP0402 | G3: =IF($A3="","",IFERROR(INDEX('2. Schematic Parts'!$D$2:$D$3001,MATCH($A3,'2. Schematic Parts'!$A$2:$A$3001,0))&"","NOT FOUND")) -> EDU-100123-001 | H3: =IF($A3="","",IF(COUNTIF('2. Schematic Parts'!$A$2:$A$3001,$A3)=0,"NOT IN SCHEMATIC","OK")) -> OK | I3: =IF($A3="","",IF($H3="NOT IN SCHEMATIC","",IF(UPPER(TRIM($C3))=UPPER(TRIM($E3)),"OK","MISMATCH"))) -> OK | J3: =IF($A3="","",IF($H3="NOT IN SCHEMATIC","",IF($F3="","NO SCH DECAL",IF($D3="","",IF(UPPER(TRIM($D3))=UPPER(TRIM($F3)),"OK","MISMATCH"))))) -> OK | K3: =IF($A3="","",SUMPRODUCT(--ISNUMBER(SEARCH(","&TRIM($A3)&",",","&SUBSTITUTE('1. Master BOM'!$D$2:$D$400," ","")&",")))) -> 1 | L3: =IF($A3="","",IF($K3<>1,0,SUMPRODUCT(ISNUMBER(SEARCH(","&TRIM($A3)&",",","&SUBSTITUTE('1. Master BOM'!$D$2:$D$400," ","")&","))*ROW('1. Master BOM'!$D$2:$D$400)))) -> 2 | M3: =IF($A3="","",IF($K3=0,"NOT IN BOM",IF($K3>1,"MULTIPLE BOM LINES","OK"))) -> OK | N3: =IF($A3="","",IF($L3=0,"—",INDEX('1. Master BOM'!$A$1:$A$400,$L3))) -> 1 | O3: =IF($A3="","",IF($L3=0,"—",INDEX('1. Master BOM'!$B$1:$B$400,$L3))) -> EDU-100123-001 | P3: =IF($A3="","",IF(OR($H3="NOT IN SCHEMATIC",$O3="—"),"",IF($G3="","NO SCH PN",IF(UPPER(TRIM($G3))=UPPER(TRIM($O3)),"OK","MISMATCH")))) -> OK | Q3: =IF($A3="","",IF($L3=0,"—",INDEX('1. Master BOM'!$E$1:$E$400,$L3))) -> CAP, CER, 100pF, 5%, 50V, 0402 | R3: =IF($A3="","",IF($L3=0,"—",IF(T(INDEX('1. Master BOM'!$F$1:$F$400,$L3))="","(not set)",INDEX('1. Master BOM'!$F$1:$F$400,$L3)))) -> 0402 | S3: =IF($A3="","",IF(OR($R3="—",$R3="(not set)",$D3=""),"",IF(ISNUMBER(SEARCH(SUBSTITUTE(SUBSTITUTE(SUBSTITUTE($R3,"-",""),"_","")," ",""),SUBSTITUTE(SUBSTITUTE(SUBSTITUTE($D3,"-",""),"_","")," ",""))),"OK","CHECK"))) -> OK | T3: =IF($A3="","",IF(OR($H3="NOT IN SCHEMATIC",$I3="MISMATCH",$J3="MISMATCH",$P3="MISMATCH",$M3<>"OK"),"REVIEW","OK")) -> OK | U3: Fail - Missing | V3: AB | W3: 46217 | X3: Example row — clear U:X before use
A4: =IF('3. Layout Parts'!$A4="","",TRIM('3. Layout Parts'!$A4)) -> U1 | B4: =IF($A4="","",'3. Layout Parts'!$D4) -> Top | C4: =IF($A4="","",'3. Layout Parts'!$B4) -> MMIC_PA_XB | D4: =IF($A4="","",'3. Layout Parts'!$C4) -> QFN24_4X4 | E4: =IF($A4="","",IFERROR(INDEX('2. Schematic Parts'!$B$2:$B$3001,MATCH($A4,'2. Schematic Parts'!$A$2:$A$3001,0)),"NOT FOUND")) -> MMIC_PA_XB | F4: =IF($A4="","",IFERROR(INDEX('2. Schematic Parts'!$C$2:$C$3001,MATCH($A4,'2. Schematic Parts'!$A$2:$A$3001,0))&"","NOT FOUND")) -> QFN24_4X4 | G4: =IF($A4="","",IFERROR(INDEX('2. Schematic Parts'!$D$2:$D$3001,MATCH($A4,'2. Schematic Parts'!$A$2:$A$3001,0))&"","NOT FOUND")) -> EDU-100456-001 | H4: =IF($A4="","",IF(COUNTIF('2. Schematic Parts'!$A$2:$A$3001,$A4)=0,"NOT IN SCHEMATIC","OK")) -> OK | I4: =IF($A4="","",IF($H4="NOT IN SCHEMATIC","",IF(UPPER(TRIM($C4))=UPPER(TRIM($E4)),"OK","MISMATCH"))) -> OK | J4: =IF($A4="","",IF($H4="NOT IN SCHEMATIC","",IF($F4="","NO SCH DECAL",IF($D4="","",IF(UPPER(TRIM($D4))=UPPER(TRIM($F4)),"OK","MISMATCH"))))) -> OK | K4: =IF($A4="","",SUMPRODUCT(--ISNUMBER(SEARCH(","&TRIM($A4)&",",","&SUBSTITUTE('1. Master BOM'!$D$2:$D$400," ","")&",")))) -> 1 | L4: =IF($A4="","",IF($K4<>1,0,SUMPRODUCT(ISNUMBER(SEARCH(","&TRIM($A4)&",",","&SUBSTITUTE('1. Master BOM'!$D$2:$D$400," ","")&","))*ROW('1. Master BOM'!$D$2:$D$400)))) -> 3 | M4: =IF($A4="","",IF($K4=0,"NOT IN BOM",IF($K4>1,"MULTIPLE BOM LINES","OK"))) -> OK | N4: =IF($A4="","",IF($L4=0,"—",INDEX('1. Master BOM'!$A$1:$A$400,$L4))) -> 2 | O4: =IF($A4="","",IF($L4=0,"—",INDEX('1. Master BOM'!$B$1:$B$400,$L4))) -> EDU-100456-001 | P4: =IF($A4="","",IF(OR($H4="NOT IN SCHEMATIC",$O4="—"),"",IF($G4="","NO SCH PN",IF(UPPER(TRIM($G4))=UPPER(TRIM($O4)),"OK","MISMATCH")))) -> OK | Q4: =IF($A4="","",IF($L4=0,"—",INDEX('1. Master BOM'!$E$1:$E$400,$L4))) -> MMIC, GaN PA, X-BAND, QFN-24 | R4: =IF($A4="","",IF($L4=0,"—",IF(T(INDEX('1. Master BOM'!$F$1:$F$400,$L4))="","(not set)",INDEX('1. Master BOM'!$F$1:$F$400,$L4)))) -> QFN24 | S4: =IF($A4="","",IF(OR($R4="—",$R4="(not set)",$D4=""),"",IF(ISNUMBER(SEARCH(SUBSTITUTE(SUBSTITUTE(SUBSTITUTE($R4,"-",""),"_","")," ",""),SUBSTITUTE(SUBSTITUTE(SUBSTITUTE($D4,"-",""),"_","")," ",""))),"OK","CHECK"))) -> OK | T4: =IF($A4="","",IF(OR($H4="NOT IN SCHEMATIC",$I4="MISMATCH",$J4="MISMATCH",$P4="MISMATCH",$M4<>"OK"),"REVIEW","OK")) -> OK
A5: =IF('3. Layout Parts'!$A5="","",TRIM('3. Layout Parts'!$A5)) -> J1 | B5: =IF($A5="","",'3. Layout Parts'!$D5) -> Bottom | C5: =IF($A5="","",'3. Layout Parts'!$B5) -> SMPM_CONN | D5: =IF($A5="","",'3. Layout Parts'!$C5) -> SMPM_SMT | E5: =IF($A5="","",IFERROR(INDEX('2. Schematic Parts'!$B$2:$B$3001,MATCH($A5,'2. Schematic Parts'!$A$2:$A$3001,0)),"NOT FOUND")) -> SMPM_CONN | F5: =IF($A5="","",IFERROR(INDEX('2. Schematic Parts'!$C$2:$C$3001,MATCH($A5,'2. Schematic Parts'!$A$2:$A$3001,0))&"","NOT FOUND")) -> SMPM_SMT | G5: =IF($A5="","",IFERROR(INDEX('2. Schematic Parts'!$D$2:$D$3001,MATCH($A5,'2. Schematic Parts'!$A$2:$A$3001,0))&"","NOT FOUND")) | H5: =IF($A5="","",IF(COUNTIF('2. Schematic Parts'!$A$2:$A$3001,$A5)=0,"NOT IN SCHEMATIC","OK")) -> OK | I5: =IF($A5="","",IF($H5="NOT IN SCHEMATIC","",IF(UPPER(TRIM($C5))=UPPER(TRIM($E5)),"OK","MISMATCH"))) -> OK | J5: =IF($A5="","",IF($H5="NOT IN SCHEMATIC","",IF($F5="","NO SCH DECAL",IF($D5="","",IF(UPPER(TRIM($D5))=UPPER(TRIM($F5)),"OK","MISMATCH"))))) -> OK | K5: =IF($A5="","",SUMPRODUCT(--ISNUMBER(SEARCH(","&TRIM($A5)&",",","&SUBSTITUTE('1. Master BOM'!$D$2:$D$400," ","")&",")))) -> 1 | L5: =IF($A5="","",IF($K5<>1,0,SUMPRODUCT(ISNUMBER(SEARCH(","&TRIM($A5)&",",","&SUBSTITUTE('1. Master BOM'!$D$2:$D$400," ","")&","))*ROW('1. Master BOM'!$D$2:$D$400)))) -> 4 | M5: =IF($A5="","",IF($K5=0,"NOT IN BOM",IF($K5>1,"MULTIPLE BOM LINES","OK"))) -> OK | N5: =IF($A5="","",IF($L5=0,"—",INDEX('1. Master BOM'!$A$1:$A$400,$L5))) -> 3 | O5: =IF($A5="","",IF($L5=0,"—",INDEX('1. Master BOM'!$B$1:$B$400,$L5))) -> EDU-100789-001 | P5: =IF($A5="","",IF(OR($H5="NOT IN SCHEMATIC",$O5="—"),"",IF($G5="","NO SCH PN",IF(UPPER(TRIM($G5))=UPPER(TRIM($O5)),"OK","MISMATCH")))) -> NO SCH PN | Q5: =IF($A5="","",IF($L5=0,"—",INDEX('1. Master BOM'!$E$1:$E$400,$L5))) -> CONNECTOR, RF, SMPM, PCB MOUNT | R5: =IF($A5="","",IF($L5=0,"—",IF(T(INDEX('1. Master BOM'!$F$1:$F$400,$L5))="","(not set)",INDEX('1. Master BOM'!$F$1:$F$400,$L5)))) -> SMPM | S5: =IF($A5="","",IF(OR($R5="—",$R5="(not set)",$D5=""),"",IF(ISNUMBER(SEARCH(SUBSTITUTE(SUBSTITUTE(SUBSTITUTE($R5,"-",""),"_","")," ",""),SUBSTITUTE(SUBSTITUTE(SUBSTITUTE($D5,"-",""),"_","")," ",""))),"OK","CHECK"))) -> OK | T5: =IF($A5="","",IF(OR($H5="NOT IN SCHEMATIC",$I5="MISMATCH",$J5="MISMATCH",$P5="MISMATCH",$M5<>"OK"),"REVIEW","OK")) -> OK
A6: =IF('3. Layout Parts'!$A6="","",TRIM('3. Layout Parts'!$A6)) | B6: =IF($A6="","",'3. Layout Parts'!$D6) | C6: =IF($A6="","",'3. Layout Parts'!$B6) | D6: =IF($A6="","",'3. Layout Parts'!$C6) | E6: =IF($A6="","",IFERROR(INDEX('2. Schematic Parts'!$B$2:$B$3001,MATCH($A6,'2. Schematic Parts'!$A$2:$A$3001,0)),"NOT FOUND")) | F6: =IF($A6="","",IFERROR(INDEX('2. Schematic Parts'!$C$2:$C$3001,MATCH($A6,'2. Schematic Parts'!$A$2:$A$3001,0))&"","NOT FOUND")) | G6: =IF($A6="","",IFERROR(INDEX('2. Schematic Parts'!$D$2:$D$3001,MATCH($A6,'2. Schematic Parts'!$A$2:$A$3001,0))&"","NOT FOUND")) | H6: =IF($A6="","",IF(COUNTIF('2. Schematic Parts'!$A$2:$A$3001,$A6)=0,"NOT IN SCHEMATIC","OK")) | I6: =IF($A6="","",IF($H6="NOT IN SCHEMATIC","",IF(UPPER(TRIM($C6))=UPPER(TRIM($E6)),"OK","MISMATCH"))) | J6: =IF($A6="","",IF($H6="NOT IN SCHEMATIC","",IF($F6="","NO SCH DECAL",IF($D6="","",IF(UPPER(TRIM($D6))=UPPER(TRIM($F6)),"OK","MISMATCH"))))) | K6: =IF($A6="","",SUMPRODUCT(--ISNUMBER(SEARCH(","&TRIM($A6)&",",","&SUBSTITUTE('1. Master BOM'!$D$2:$D$400," ","")&",")))) | L6: =IF($A6="","",IF($K6<>1,0,SUMPRODUCT(ISNUMBER(SEARCH(","&TRIM($A6)&",",","&SUBSTITUTE('1. Master BOM'!$D$2:$D$400," ","")&","))*ROW('1. Master BOM'!$D$2:$D$400)))) | M6: =IF($A6="","",IF($K6=0,"NOT IN BOM",IF($K6>1,"MULTIPLE BOM LINES","OK"))) | N6: =IF($A6="","",IF($L6=0,"—",INDEX('1. Master BOM'!$A$1:$A$400,$L6))) | O6: =IF($A6="","",IF($L6=0,"—",INDEX('1. Master BOM'!$B$1:$B$400,$L6))) | P6: =IF($A6="","",IF(OR($H6="NOT IN SCHEMATIC",$O6="—"),"",IF($G6="","NO SCH PN",IF(UPPER(TRIM($G6))=UPPER(TRIM($O6)),"OK","MISMATCH")))) | Q6: =IF($A6="","",IF($L6=0,"—",INDEX('1. Master BOM'!$E$1:$E$400,$L6))) | R6: =IF($A6="","",IF($L6=0,"—",IF(T(INDEX('1. Master BOM'!$F$1:$F$400,$L6))="","(not set)",INDEX('1. Master BOM'!$F$1:$F$400,$L6)))) | S6: =IF($A6="","",IF(OR($R6="—",$R6="(not set)",$D6=""),"",IF(ISNUMBER(SEARCH(SUBSTITUTE(SUBSTITUTE(SUBSTITUTE($R6,"-",""),"_","")," ",""),SUBSTITUTE(SUBSTITUTE(SUBSTITUTE($D6,"-",""),"_","")," ",""))),"OK","CHECK"))) | T6: =IF($A6="","",IF(OR($H6="NOT IN SCHEMATIC",$I6="MISMATCH",$J6="MISMATCH",$P6="MISMATCH",$M6<>"OK"),"REVIEW","OK"))
A7: =IF('3. Layout Parts'!$A7="","",TRIM('3. Layout Parts'!$A7)) | B7: =IF($A7="","",'3. Layout Parts'!$D7) | C7: =IF($A7="","",'3. Layout Parts'!$B7) | D7: =IF($A7="","",'3. Layout Parts'!$C7) | E7: =IF($A7="","",IFERROR(INDEX('2. Schematic Parts'!$B$2:$B$3001,MATCH($A7,'2. Schematic Parts'!$A$2:$A$3001,0)),"NOT FOUND")) | F7: =IF($A7="","",IFERROR(INDEX('2. Schematic Parts'!$C$2:$C$3001,MATCH($A7,'2. Schematic Parts'!$A$2:$A$3001,0))&"","NOT FOUND")) | G7: =IF($A7="","",IFERROR(INDEX('2. Schematic Parts'!$D$2:$D$3001,MATCH($A7,'2. Schematic Parts'!$A$2:$A$3001,0))&"","NOT FOUND")) | H7: =IF($A7="","",IF(COUNTIF('2. Schematic Parts'!$A$2:$A$3001,$A7)=0,"NOT IN SCHEMATIC","OK")) | I7: =IF($A7="","",IF($H7="NOT IN SCHEMATIC","",IF(UPPER(TRIM($C7))=UPPER(TRIM($E7)),"OK","MISMATCH"))) | J7: =IF($A7="","",IF($H7="NOT IN SCHEMATIC","",IF($F7="","NO SCH DECAL",IF($D7="","",IF(UPPER(TRIM($D7))=UPPER(TRIM($F7)),"OK","MISMATCH"))))) | K7: =IF($A7="","",SUMPRODUCT(--ISNUMBER(SEARCH(","&TRIM($A7)&",",","&SUBSTITUTE('1. Master BOM'!$D$2:$D$400," ","")&",")))) | L7: =IF($A7="","",IF($K7<>1,0,SUMPRODUCT(ISNUMBER(SEARCH(","&TRIM($A7)&",",","&SUBSTITUTE('1. Master BOM'!$D$2:$D$400," ","")&","))*ROW('1. Master BOM'!$D$2:$D$400)))) | M7: =IF($A7="","",IF($K7=0,"NOT IN BOM",IF($K7>1,"MULTIPLE BOM LINES","OK"))) | N7: =IF($A7="","",IF($L7=0,"—",INDEX('1. Master BOM'!$A$1:$A$400,$L7))) | O7: =IF($A7="","",IF($L7=0,"—",INDEX('1. Master BOM'!$B$1:$B$400,$L7))) | P7: =IF($A7="","",IF(OR($H7="NOT IN SCHEMATIC",$O7="—"),"",IF($G7="","NO SCH PN",IF(UPPER(TRIM($G7))=UPPER(TRIM($O7)),"OK","MISMATCH")))) | Q7: =IF($A7="","",IF($L7=0,"—",INDEX('1. Master BOM'!$E$1:$E$400,$L7))) | R7: =IF($A7="","",IF($L7=0,"—",IF(T(INDEX('1. Master BOM'!$F$1:$F$400,$L7))="","(not set)",INDEX('1. Master BOM'!$F$1:$F$400,$L7)))) | S7: =IF($A7="","",IF(OR($R7="—",$R7="(not set)",$D7=""),"",IF(ISNUMBER(SEARCH(SUBSTITUTE(SUBSTITUTE(SUBSTITUTE($R7,"-",""),"_","")," ",""),SUBSTITUTE(SUBSTITUTE(SUBSTITUTE($D7,"-",""),"_","")," ",""))),"OK","CHECK"))) | T7: =IF($A7="","",IF(OR($H7="NOT IN SCHEMATIC",$I7="MISMATCH",$J7="MISMATCH",$P7="MISMATCH",$M7<>"OK"),"REVIEW","OK"))
A8: =IF('3. Layout Parts'!$A8="","",TRIM('3. Layout Parts'!$A8)) | B8: =IF($A8="","",'3. Layout Parts'!$D8) | C8: =IF($A8="","",'3. Layout Parts'!$B8) | D8: =IF($A8="","",'3. Layout Parts'!$C8) | E8: =IF($A8="","",IFERROR(INDEX('2. Schematic Parts'!$B$2:$B$3001,MATCH($A8,'2. Schematic Parts'!$A$2:$A$3001,0)),"NOT FOUND")) | F8: =IF($A8="","",IFERROR(INDEX('2. Schematic Parts'!$C$2:$C$3001,MATCH($A8,'2. Schematic Parts'!$A$2:$A$3001,0))&"","NOT FOUND")) | G8: =IF($A8="","",IFERROR(INDEX('2. Schematic Parts'!$D$2:$D$3001,MATCH($A8,'2. Schematic Parts'!$A$2:$A$3001,0))&"","NOT FOUND")) | H8: =IF($A8="","",IF(COUNTIF('2. Schematic Parts'!$A$2:$A$3001,$A8)=0,"NOT IN SCHEMATIC","OK")) | I8: =IF($A8="","",IF($H8="NOT IN SCHEMATIC","",IF(UPPER(TRIM($C8))=UPPER(TRIM($E8)),"OK","MISMATCH"))) | J8: =IF($A8="","",IF($H8="NOT IN SCHEMATIC","",IF($F8="","NO SCH DECAL",IF($D8="","",IF(UPPER(TRIM($D8))=UPPER(TRIM($F8)),"OK","MISMATCH"))))) | K8: =IF($A8="","",SUMPRODUCT(--ISNUMBER(SEARCH(","&TRIM($A8)&",",","&SUBSTITUTE('1. Master BOM'!$D$2:$D$400," ","")&",")))) | L8: =IF($A8="","",IF($K8<>1,0,SUMPRODUCT(ISNUMBER(SEARCH(","&TRIM($A8)&",",","&SUBSTITUTE('1. Master BOM'!$D$2:$D$400," ","")&","))*ROW('1. Master BOM'!$D$2:$D$400)))) | M8: =IF($A8="","",IF($K8=0,"NOT IN BOM",IF($K8>1,"MULTIPLE BOM LINES","OK"))) | N8: =IF($A8="","",IF($L8=0,"—",INDEX('1. Master BOM'!$A$1:$A$400,$L8))) | O8: =IF($A8="","",IF($L8=0,"—",INDEX('1. Master BOM'!$B$1:$B$400,$L8))) | P8: =IF($A8="","",IF(OR($H8="NOT IN SCHEMATIC",$O8="—"),"",IF($G8="","NO SCH PN",IF(UPPER(TRIM($G8))=UPPER(TRIM($O8)),"OK","MISMATCH")))) | Q8: =IF($A8="","",IF($L8=0,"—",INDEX('1. Master BOM'!$E$1:$E$400,$L8))) | R8: =IF($A8="","",IF($L8=0,"—",IF(T(INDEX('1. Master BOM'!$F$1:$F$400,$L8))="","(not set)",INDEX('1. Master BOM'!$F$1:$F$400,$L8)))) | S8: =IF($A8="","",IF(OR($R8="—",$R8="(not set)",$D8=""),"",IF(ISNUMBER(SEARCH(SUBSTITUTE(SUBSTITUTE(SUBSTITUTE($R8,"-",""),"_","")," ",""),SUBSTITUTE(SUBSTITUTE(SUBSTITUTE($D8,"-",""),"_","")," ",""))),"OK","CHECK"))) | T8: =IF($A8="","",IF(OR($H8="NOT IN SCHEMATIC",$I8="MISMATCH",$J8="MISMATCH",$P8="MISMATCH",$M8<>"OK"),"REVIEW","OK"))
A9: =IF('3. Layout Parts'!$A9="","",TRIM('3. Layout Parts'!$A9)) | B9: =IF($A9="","",'3. Layout Parts'!$D9) | C9: =IF($A9="","",'3. Layout Parts'!$B9) | D9: =IF($A9="","",'3. Layout Parts'!$C9) | E9: =IF($A9="","",IFERROR(INDEX('2. Schematic Parts'!$B$2:$B$3001,MATCH($A9,'2. Schematic Parts'!$A$2:$A$3001,0)),"NOT FOUND")) | F9: =IF($A9="","",IFERROR(INDEX('2. Schematic Parts'!$C$2:$C$3001,MATCH($A9,'2. Schematic Parts'!$A$2:$A$3001,0))&"","NOT FOUND")) | G9: =IF($A9="","",IFERROR(INDEX('2. Schematic Parts'!$D$2:$D$3001,MATCH($A9,'2. Schematic Parts'!$A$2:$A$3001,0))&"","NOT FOUND")) | H9: =IF($A9="","",IF(COUNTIF('2. Schematic Parts'!$A$2:$A$3001,$A9)=0,"NOT IN SCHEMATIC","OK")) | I9: =IF($A9="","",IF($H9="NOT IN SCHEMATIC","",IF(UPPER(TRIM($C9))=UPPER(TRIM($E9)),"OK","MISMATCH"))) | J9: =IF($A9="","",IF($H9="NOT IN SCHEMATIC","",IF($F9="","NO SCH DECAL",IF($D9="","",IF(UPPER(TRIM($D9))=UPPER(TRIM($F9)),"OK","MISMATCH"))))) | K9: =IF($A9="","",SUMPRODUCT(--ISNUMBER(SEARCH(","&TRIM($A9)&",",","&SUBSTITUTE('1. Master BOM'!$D$2:$D$400," ","")&",")))) | L9: =IF($A9="","",IF($K9<>1,0,SUMPRODUCT(ISNUMBER(SEARCH(","&TRIM($A9)&",",","&SUBSTITUTE('1. Master BOM'!$D$2:$D$400," ","")&","))*ROW('1. Master BOM'!$D$2:$D$400)))) | M9: =IF($A9="","",IF($K9=0,"NOT IN BOM",IF($K9>1,"MULTIPLE BOM LINES","OK"))) | N9: =IF($A9="","",IF($L9=0,"—",INDEX('1. Master BOM'!$A$1:$A$400,$L9))) | O9: =IF($A9="","",IF($L9=0,"—",INDEX('1. Master BOM'!$B$1:$B$400,$L9))) | P9: =IF($A9="","",IF(OR($H9="NOT IN SCHEMATIC",$O9="—"),"",IF($G9="","NO SCH PN",IF(UPPER(TRIM($G9))=UPPER(TRIM($O9)),"OK","MISMATCH")))) | Q9: =IF($A9="","",IF($L9=0,"—",INDEX('1. Master BOM'!$E$1:$E$400,$L9))) | R9: =IF($A9="","",IF($L9=0,"—",IF(T(INDEX('1. Master BOM'!$F$1:$F$400,$L9))="","(not set)",INDEX('1. Master BOM'!$F$1:$F$400,$L9)))) | S9: =IF($A9="","",IF(OR($R9="—",$R9="(not set)",$D9=""),"",IF(ISNUMBER(SEARCH(SUBSTITUTE(SUBSTITUTE(SUBSTITUTE($R9,"-",""),"_","")," ",""),SUBSTITUTE(SUBSTITUTE(SUBSTITUTE($D9,"-",""),"_","")," ",""))),"OK","CHECK"))) | T9: =IF($A9="","",IF(OR($H9="NOT IN SCHEMATIC",$I9="MISMATCH",$J9="MISMATCH",$P9="MISMATCH",$M9<>"OK"),"REVIEW","OK"))
A10: =IF('3. Layout Parts'!$A10="","",TRIM('3. Layout Parts'!$A10)) | B10: =IF($A10="","",'3. Layout Parts'!$D10) | C10: =IF($A10="","",'3. Layout Parts'!$B10) | D10: =IF($A10="","",'3. Layout Parts'!$C10) | E10: =IF($A10="","",IFERROR(INDEX('2. Schematic Parts'!$B$2:$B$3001,MATCH($A10,'2. Schematic Parts'!$A$2:$A$3001,0)),"NOT FOUND")) | F10: =IF($A10="","",IFERROR(INDEX('2. Schematic Parts'!$C$2:$C$3001,MATCH($A10,'2. Schematic Parts'!$A$2:$A$3001,0))&"","NOT FOUND")) | G10: =IF($A10="","",IFERROR(INDEX('2. Schematic Parts'!$D$2:$D$3001,MATCH($A10,'2. Schematic Parts'!$A$2:$A$3001,0))&"","NOT FOUND")) | H10: =IF($A10="","",IF(COUNTIF('2. Schematic Parts'!$A$2:$A$3001,$A10)=0,"NOT IN SCHEMATIC","OK")) | I10: =IF($A10="","",IF($H10="NOT IN SCHEMATIC","",IF(UPPER(TRIM($C10))=UPPER(TRIM($E10)),"OK","MISMATCH"))) | J10: =IF($A10="","",IF($H10="NOT IN SCHEMATIC","",IF($F10="","NO SCH DECAL",IF($D10="","",IF(UPPER(TRIM($D10))=UPPER(TRIM($F10)),"OK","MISMATCH"))))) | K10: =IF($A10="","",SUMPRODUCT(--ISNUMBER(SEARCH(","&TRIM($A10)&",",","&SUBSTITUTE('1. Master BOM'!$D$2:$D$400," ","")&",")))) | L10: =IF($A10="","",IF($K10<>1,0,SUMPRODUCT(ISNUMBER(SEARCH(","&TRIM($A10)&",",","&SUBSTITUTE('1. Master BOM'!$D$2:$D$400," ","")&","))*ROW('1. Master BOM'!$D$2:$D$400)))) | M10: =IF($A10="","",IF($K10=0,"NOT IN BOM",IF($K10>1,"MULTIPLE BOM LINES","OK"))) | N10: =IF($A10="","",IF($L10=0,"—",INDEX('1. Master BOM'!$A$1:$A$400,$L10))) | O10: =IF($A10="","",IF($L10=0,"—",INDEX('1. Master BOM'!$B$1:$B$400,$L10))) | P10: =IF($A10="","",IF(OR($H10="NOT IN SCHEMATIC",$O10="—"),"",IF($G10="","NO SCH PN",IF(UPPER(TRIM($G10))=UPPER(TRIM($O10)),"OK","MISMATCH")))) | Q10: =IF($A10="","",IF($L10=0,"—",INDEX('1. Master BOM'!$E$1:$E$400,$L10))) | R10: =IF($A10="","",IF($L10=0,"—",IF(T(INDEX('1. Master BOM'!$F$1:$F$400,$L10))="","(not set)",INDEX('1. Master BOM'!$F$1:$F$400,$L10)))) | S10: =IF($A10="","",IF(OR($R10="—",$R10="(not set)",$D10=""),"",IF(ISNUMBER(SEARCH(SUBSTITUTE(SUBSTITUTE(SUBSTITUTE($R10,"-",""),"_","")," ",""),SUBSTITUTE(SUBSTITUTE(SUBSTITUTE($D10,"-",""),"_","")," ",""))),"OK","CHECK"))) | T10: =IF($A10="","",IF(OR($H10="NOT IN SCHEMATIC",$I10="MISMATCH",$J10="MISMATCH",$P10="MISMATCH",$M10<>"OK"),"REVIEW","OK"))
A11: =IF('3. Layout Parts'!$A11="","",TRIM('3. Layout Parts'!$A11)) | B11: =IF($A11="","",'3. Layout Parts'!$D11) | C11: =IF($A11="","",'3. Layout Parts'!$B11) | D11: =IF($A11="","",'3. Layout Parts'!$C11) | E11: =IF($A11="","",IFERROR(INDEX('2. Schematic Parts'!$B$2:$B$3001,MATCH($A11,'2. Schematic Parts'!$A$2:$A$3001,0)),"NOT FOUND")) | F11: =IF($A11="","",IFERROR(INDEX('2. Schematic Parts'!$C$2:$C$3001,MATCH($A11,'2. Schematic Parts'!$A$2:$A$3001,0))&"","NOT FOUND")) | G11: =IF($A11="","",IFERROR(INDEX('2. Schematic Parts'!$D$2:$D$3001,MATCH($A11,'2. Schematic Parts'!$A$2:$A$3001,0))&"","NOT FOUND")) | H11: =IF($A11="","",IF(COUNTIF('2. Schematic Parts'!$A$2:$A$3001,$A11)=0,"NOT IN SCHEMATIC","OK")) | I11: =IF($A11="","",IF($H11="NOT IN SCHEMATIC","",IF(UPPER(TRIM($C11))=UPPER(TRIM($E11)),"OK","MISMATCH"))) | J11: =IF($A11="","",IF($H11="NOT IN SCHEMATIC","",IF($F11="","NO SCH DECAL",IF($D11="","",IF(UPPER(TRIM($D11))=UPPER(TRIM($F11)),"OK","MISMATCH"))))) | K11: =IF($A11="","",SUMPRODUCT(--ISNUMBER(SEARCH(","&TRIM($A11)&",",","&SUBSTITUTE('1. Master BOM'!$D$2:$D$400," ","")&",")))) | L11: =IF($A11="","",IF($K11<>1,0,SUMPRODUCT(ISNUMBER(SEARCH(","&TRIM($A11)&",",","&SUBSTITUTE('1. Master BOM'!$D$2:$D$400," ","")&","))*ROW('1. Master BOM'!$D$2:$D$400)))) | M11: =IF($A11="","",IF($K11=0,"NOT IN BOM",IF($K11>1,"MULTIPLE BOM LINES","OK"))) | N11: =IF($A11="","",IF($L11=0,"—",INDEX('1. Master BOM'!$A$1:$A$400,$L11))) | O11: =IF($A11="","",IF($L11=0,"—",INDEX('1. Master BOM'!$B$1:$B$400,$L11))) | P11: =IF($A11="","",IF(OR($H11="NOT IN SCHEMATIC",$O11="—"),"",IF($G11="","NO SCH PN",IF(UPPER(TRIM($G11))=UPPER(TRIM($O11)),"OK","MISMATCH")))) | Q11: =IF($A11="","",IF($L11=0,"—",INDEX('1. Master BOM'!$E$1:$E$400,$L11))) | R11: =IF($A11="","",IF($L11=0,"—",IF(T(INDEX('1. Master BOM'!$F$1:$F$400,$L11))="","(not set)",INDEX('1. Master BOM'!$F$1:$F$400,$L11)))) | S11: =IF($A11="","",IF(OR($R11="—",$R11="(not set)",$D11=""),"",IF(ISNUMBER(SEARCH(SUBSTITUTE(SUBSTITUTE(SUBSTITUTE($R11,"-",""),"_","")," ",""),SUBSTITUTE(SUBSTITUTE(SUBSTITUTE($D11,"-",""),"_","")," ",""))),"OK","CHECK"))) | T11: =IF($A11="","",IF(OR($H11="NOT IN SCHEMATIC",$I11="MISMATCH",$J11="MISMATCH",$P11="MISMATCH",$M11<>"OK"),"REVIEW","OK"))
A12: =IF('3. Layout Parts'!$A12="","",TRIM('3. Layout Parts'!$A12)) | B12: =IF($A12="","",'3. Layout Parts'!$D12) | C12: =IF($A12="","",'3. Layout Parts'!$B12) | D12: =IF($A12="","",'3. Layout Parts'!$C12) | E12: =IF($A12="","",IFERROR(INDEX('2. Schematic Parts'!$B$2:$B$3001,MATCH($A12,'2. Schematic Parts'!$A$2:$A$3001,0)),"NOT FOUND")) | F12: =IF($A12="","",IFERROR(INDEX('2. Schematic Parts'!$C$2:$C$3001,MATCH($A12,'2. Schematic Parts'!$A$2:$A$3001,0))&"","NOT FOUND")) | G12: =IF($A12="","",IFERROR(INDEX('2. Schematic Parts'!$D$2:$D$3001,MATCH($A12,'2. Schematic Parts'!$A$2:$A$3001,0))&"","NOT FOUND")) | H12: =IF($A12="","",IF(COUNTIF('2. Schematic Parts'!$A$2:$A$3001,$A12)=0,"NOT IN SCHEMATIC","OK")) | I12: =IF($A12="","",IF($H12="NOT IN SCHEMATIC","",IF(UPPER(TRIM($C12))=UPPER(TRIM($E12)),"OK","MISMATCH"))) | J12: =IF($A12="","",IF($H12="NOT IN SCHEMATIC","",IF($F12="","NO SCH DECAL",IF($D12="","",IF(UPPER(TRIM($D12))=UPPER(TRIM($F12)),"OK","MISMATCH"))))) | K12: =IF($A12="","",SUMPRODUCT(--ISNUMBER(SEARCH(","&TRIM($A12)&",",","&SUBSTITUTE('1. Master BOM'!$D$2:$D$400," ","")&",")))) | L12: =IF($A12="","",IF($K12<>1,0,SUMPRODUCT(ISNUMBER(SEARCH(","&TRIM($A12)&",",","&SUBSTITUTE('1. Master BOM'!$D$2:$D$400," ","")&","))*ROW('1. Master BOM'!$D$2:$D$400)))) | M12: =IF($A12="","",IF($K12=0,"NOT IN BOM",IF($K12>1,"MULTIPLE BOM LINES","OK"))) | N12: =IF($A12="","",IF($L12=0,"—",INDEX('1. Master BOM'!$A$1:$A$400,$L12))) | O12: =IF($A12="","",IF($L12=0,"—",INDEX('1. Master BOM'!$B$1:$B$400,$L12))) | P12: =IF($A12="","",IF(OR($H12="NOT IN SCHEMATIC",$O12="—"),"",IF($G12="","NO SCH PN",IF(UPPER(TRIM($G12))=UPPER(TRIM($O12)),"OK","MISMATCH")))) | Q12: =IF($A12="","",IF($L12=0,"—",INDEX('1. Master BOM'!$E$1:$E$400,$L12))) | R12: =IF($A12="","",IF($L12=0,"—",IF(T(INDEX('1. Master BOM'!$F$1:$F$400,$L12))="","(not set)",INDEX('1. Master BOM'!$F$1:$F$400,$L12)))) | S12: =IF($A12="","",IF(OR($R12="—",$R12="(not set)",$D12=""),"",IF(ISNUMBER(SEARCH(SUBSTITUTE(SUBSTITUTE(SUBSTITUTE($R12,"-",""),"_","")," ",""),SUBSTITUTE(SUBSTITUTE(SUBSTITUTE($D12,"-",""),"_","")," ",""))),"OK","CHECK"))) | T12: =IF($A12="","",IF(OR($H12="NOT IN SCHEMATIC",$I12="MISMATCH",$J12="MISMATCH",$P12="MISMATCH",$M12<>"OK"),"REVIEW","OK"))
A13: =IF('3. Layout Parts'!$A13="","",TRIM('3. Layout Parts'!$A13)) | B13: =IF($A13="","",'3. Layout Parts'!$D13) | C13: =IF($A13="","",'3. Layout Parts'!$B13) | D13: =IF($A13="","",'3. Layout Parts'!$C13) | E13: =IF($A13="","",IFERROR(INDEX('2. Schematic Parts'!$B$2:$B$3001,MATCH($A13,'2. Schematic Parts'!$A$2:$A$3001,0)),"NOT FOUND")) | F13: =IF($A13="","",IFERROR(INDEX('2. Schematic Parts'!$C$2:$C$3001,MATCH($A13,'2. Schematic Parts'!$A$2:$A$3001,0))&"","NOT FOUND")) | G13: =IF($A13="","",IFERROR(INDEX('2. Schematic Parts'!$D$2:$D$3001,MATCH($A13,'2. Schematic Parts'!$A$2:$A$3001,0))&"","NOT FOUND")) | H13: =IF($A13="","",IF(COUNTIF('2. Schematic Parts'!$A$2:$A$3001,$A13)=0,"NOT IN SCHEMATIC","OK")) | I13: =IF($A13="","",IF($H13="NOT IN SCHEMATIC","",IF(UPPER(TRIM($C13))=UPPER(TRIM($E13)),"OK","MISMATCH"))) | J13: =IF($A13="","",IF($H13="NOT IN SCHEMATIC","",IF($F13="","NO SCH DECAL",IF($D13="","",IF(UPPER(TRIM($D13))=UPPER(TRIM($F13)),"OK","MISMATCH"))))) | K13: =IF($A13="","",SUMPRODUCT(--ISNUMBER(SEARCH(","&TRIM($A13)&",",","&SUBSTITUTE('1. Master BOM'!$D$2:$D$400," ","")&",")))) | L13: =IF($A13="","",IF($K13<>1,0,SUMPRODUCT(ISNUMBER(SEARCH(","&TRIM($A13)&",",","&SUBSTITUTE('1. Master BOM'!$D$2:$D$400," ","")&","))*ROW('1. Master BOM'!$D$2:$D$400)))) | M13: =IF($A13="","",IF($K13=0,"NOT IN BOM",IF($K13>1,"MULTIPLE BOM LINES","OK"))) | N13: =IF($A13="","",IF($L13=0,"—",INDEX('1. Master BOM'!$A$1:$A$400,$L13))) | O13: =IF($A13="","",IF($L13=0,"—",INDEX('1. Master BOM'!$B$1:$B$400,$L13))) | P13: =IF($A13="","",IF(OR($H13="NOT IN SCHEMATIC",$O13="—"),"",IF($G13="","NO SCH PN",IF(UPPER(TRIM($G13))=UPPER(TRIM($O13)),"OK","MISMATCH")))) | Q13: =IF($A13="","",IF($L13=0,"—",INDEX('1. Master BOM'!$E$1:$E$400,$L13))) | R13: =IF($A13="","",IF($L13=0,"—",IF(T(INDEX('1. Master BOM'!$F$1:$F$400,$L13))="","(not set)",INDEX('1. Master BOM'!$F$1:$F$400,$L13)))) | S13: =IF($A13="","",IF(OR($R13="—",$R13="(not set)",$D13=""),"",IF(ISNUMBER(SEARCH(SUBSTITUTE(SUBSTITUTE(SUBSTITUTE($R13,"-",""),"_","")," ",""),SUBSTITUTE(SUBSTITUTE(SUBSTITUTE($D13,"-",""),"_","")," ",""))),"OK","CHECK"))) | T13: =IF($A13="","",IF(OR($H13="NOT IN SCHEMATIC",$I13="MISMATCH",$J13="MISMATCH",$P13="MISMATCH",$M13<>"OK"),"REVIEW","OK"))
A14: =IF('3. Layout Parts'!$A14="","",TRIM('3. Layout Parts'!$A14)) | B14: =IF($A14="","",'3. Layout Parts'!$D14) | C14: =IF($A14="","",'3. Layout Parts'!$B14) | D14: =IF($A14="","",'3. Layout Parts'!$C14) | E14: =IF($A14="","",IFERROR(INDEX('2. Schematic Parts'!$B$2:$B$3001,MATCH($A14,'2. Schematic Parts'!$A$2:$A$3001,0)),"NOT FOUND")) | F14: =IF($A14="","",IFERROR(INDEX('2. Schematic Parts'!$C$2:$C$3001,MATCH($A14,'2. Schematic Parts'!$A$2:$A$3001,0))&"","NOT FOUND")) | G14: =IF($A14="","",IFERROR(INDEX('2. Schematic Parts'!$D$2:$D$3001,MATCH($A14,'2. Schematic Parts'!$A$2:$A$3001,0))&"","NOT FOUND")) | H14: =IF($A14="","",IF(COUNTIF('2. Schematic Parts'!$A$2:$A$3001,$A14)=0,"NOT IN SCHEMATIC","OK")) | I14: =IF($A14="","",IF($H14="NOT IN SCHEMATIC","",IF(UPPER(TRIM($C14))=UPPER(TRIM($E14)),"OK","MISMATCH"))) | J14: =IF($A14="","",IF($H14="NOT IN SCHEMATIC","",IF($F14="","NO SCH DECAL",IF($D14="","",IF(UPPER(TRIM($D14))=UPPER(TRIM($F14)),"OK","MISMATCH"))))) | K14: =IF($A14="","",SUMPRODUCT(--ISNUMBER(SEARCH(","&TRIM($A14)&",",","&SUBSTITUTE('1. Master BOM'!$D$2:$D$400," ","")&",")))) | L14: =IF($A14="","",IF($K14<>1,0,SUMPRODUCT(ISNUMBER(SEARCH(","&TRIM($A14)&",",","&SUBSTITUTE('1. Master BOM'!$D$2:$D$400," ","")&","))*ROW('1. Master BOM'!$D$2:$D$400)))) | M14: =IF($A14="","",IF($K14=0,"NOT IN BOM",IF($K14>1,"MULTIPLE BOM LINES","OK"))) | N14: =IF($A14="","",IF($L14=0,"—",INDEX('1. Master BOM'!$A$1:$A$400,$L14))) | O14: =IF($A14="","",IF($L14=0,"—",INDEX('1. Master BOM'!$B$1:$B$400,$L14))) | P14: =IF($A14="","",IF(OR($H14="NOT IN SCHEMATIC",$O14="—"),"",IF($G14="","NO SCH PN",IF(UPPER(TRIM($G14))=UPPER(TRIM($O14)),"OK","MISMATCH")))) | Q14: =IF($A14="","",IF($L14=0,"—",INDEX('1. Master BOM'!$E$1:$E$400,$L14))) | R14: =IF($A14="","",IF($L14=0,"—",IF(T(INDEX('1. Master BOM'!$F$1:$F$400,$L14))="","(not set)",INDEX('1. Master BOM'!$F$1:$F$400,$L14)))) | S14: =IF($A14="","",IF(OR($R14="—",$R14="(not set)",$D14=""),"",IF(ISNUMBER(SEARCH(SUBSTITUTE(SUBSTITUTE(SUBSTITUTE($R14,"-",""),"_","")," ",""),SUBSTITUTE(SUBSTITUTE(SUBSTITUTE($D14,"-",""),"_","")," ",""))),"OK","CHECK"))) | T14: =IF($A14="","",IF(OR($H14="NOT IN SCHEMATIC",$I14="MISMATCH",$J14="MISMATCH",$P14="MISMATCH",$M14<>"OK"),"REVIEW","OK"))
A15: =IF('3. Layout Parts'!$A15="","",TRIM('3. Layout Parts'!$A15)) | B15: =IF($A15="","",'3. Layout Parts'!$D15) | C15: =IF($A15="","",'3. Layout Parts'!$B15) | D15: =IF($A15="","",'3. Layout Parts'!$C15) | E15: =IF($A15="","",IFERROR(INDEX('2. Schematic Parts'!$B$2:$B$3001,MATCH($A15,'2. Schematic Parts'!$A$2:$A$3001,0)),"NOT FOUND")) | F15: =IF($A15="","",IFERROR(INDEX('2. Schematic Parts'!$C$2:$C$3001,MATCH($A15,'2. Schematic Parts'!$A$2:$A$3001,0))&"","NOT FOUND")) | G15: =IF($A15="","",IFERROR(INDEX('2. Schematic Parts'!$D$2:$D$3001,MATCH($A15,'2. Schematic Parts'!$A$2:$A$3001,0))&"","NOT FOUND")) | H15: =IF($A15="","",IF(COUNTIF('2. Schematic Parts'!$A$2:$A$3001,$A15)=0,"NOT IN SCHEMATIC","OK")) | I15: =IF($A15="","",IF($H15="NOT IN SCHEMATIC","",IF(UPPER(TRIM($C15))=UPPER(TRIM($E15)),"OK","MISMATCH"))) | J15: =IF($A15="","",IF($H15="NOT IN SCHEMATIC","",IF($F15="","NO SCH DECAL",IF($D15="","",IF(UPPER(TRIM($D15))=UPPER(TRIM($F15)),"OK","MISMATCH"))))) | K15: =IF($A15="","",SUMPRODUCT(--ISNUMBER(SEARCH(","&TRIM($A15)&",",","&SUBSTITUTE('1. Master BOM'!$D$2:$D$400," ","")&",")))) | L15: =IF($A15="","",IF($K15<>1,0,SUMPRODUCT(ISNUMBER(SEARCH(","&TRIM($A15)&",",","&SUBSTITUTE('1. Master BOM'!$D$2:$D$400," ","")&","))*ROW('1. Master BOM'!$D$2:$D$400)))) | M15: =IF($A15="","",IF($K15=0,"NOT IN BOM",IF($K15>1,"MULTIPLE BOM LINES","OK"))) | N15: =IF($A15="","",IF($L15=0,"—",INDEX('1. Master BOM'!$A$1:$A$400,$L15))) | O15: =IF($A15="","",IF($L15=0,"—",INDEX('1. Master BOM'!$B$1:$B$400,$L15))) | P15: =IF($A15="","",IF(OR($H15="NOT IN SCHEMATIC",$O15="—"),"",IF($G15="","NO SCH PN",IF(UPPER(TRIM($G15))=UPPER(TRIM($O15)),"OK","MISMATCH")))) | Q15: =IF($A15="","",IF($L15=0,"—",INDEX('1. Master BOM'!$E$1:$E$400,$L15))) | R15: =IF($A15="","",IF($L15=0,"—",IF(T(INDEX('1. Master BOM'!$F$1:$F$400,$L15))="","(not set)",INDEX('1. Master BOM'!$F$1:$F$400,$L15)))) | S15: =IF($A15="","",IF(OR($R15="—",$R15="(not set)",$D15=""),"",IF(ISNUMBER(SEARCH(SUBSTITUTE(SUBSTITUTE(SUBSTITUTE($R15,"-",""),"_","")," ",""),SUBSTITUTE(SUBSTITUTE(SUBSTITUTE($D15,"-",""),"_","")," ",""))),"OK","CHECK"))) | T15: =IF($A15="","",IF(OR($H15="NOT IN SCHEMATIC",$I15="MISMATCH",$J15="MISMATCH",$P15="MISMATCH",$M15<>"OK"),"REVIEW","OK"))
... A3001: =IF('3. Layout Parts'!$A3001="","",TRIM('3. Layout Parts'!$A3001)) | B3001: =IF($A3001="","",'3. Layout Parts'!$D3001) | C3001: =IF($A3001="","",'3. Layout Parts'!$B3001) | D3001: =IF($A3001="","",'3. Layout Parts'!$C3001) | E3001: =IF($A3001="","",IFERROR(INDEX('2. Schematic Parts'!$B$2:$B$3001,MATCH($A3001,'2. Schematic Parts'!$A$2:$A$3001,0)),"NOT FOUND")) | F3001: =IF($A3001="","",IFERROR(INDEX('2. Schematic Parts'!$C$2:$C$3001,MATCH($A3001,'2. Schematic Parts'!$A$2:$A$3001,0))&"","NOT FOUND")) | G3001: =IF($A3001="","",IFERROR(INDEX('2. Schematic Parts'!$D$2:$D$3001,MATCH($A3001,'2. Schematic Parts'!$A$2:$A$3001,0))&"","NOT FOUND")) | H3001: =IF($A3001="","",IF(COUNTIF('2. Schematic Parts'!$A$2:$A$3001,$A3001)=0,"NOT IN SCHEMATIC","OK")) | I3001: =IF($A3001="","",IF($H3001="NOT IN SCHEMATIC","",IF(UPPER(TRIM($C3001))=UPPER(TRIM($E3001)),"OK","MISMATCH"))) | J3001: =IF($A3001="","",IF($H3001="NOT IN SCHEMATIC","",IF($F3001="","NO SCH DECAL",IF($D3001="","",IF(UPPER(TRIM($D3001))=UPPER(TRIM($F3001)),"OK","MISMATCH"))))) | K3001: =IF($A3001="","",SUMPRODUCT(--ISNUMBER(SEARCH(","&TRIM($A3001)&",",","&SUBSTITUTE('1. Master BOM'!$D$2:$D$400," ","")&",")))) | L3001: =IF($A3001="","",IF($K3001<>1,0,SUMPRODUCT(ISNUMBER(SEARCH(","&TRIM($A3001)&",",","&SUBSTITUTE('1. Master BOM'!$D$2:$D$400," ","")&","))*ROW('1. Master BOM'!$D$2:$D$400)))) | M3001: =IF($A3001="","",IF($K3001=0,"NOT IN BOM",IF($K3001>1,"MULTIPLE BOM LINES","OK"))) | N3001: =IF($A3001="","",IF($L3001=0,"—",INDEX('1. Master BOM'!$A$1:$A$400,$L3001))) | O3001: =IF($A3001="","",IF($L3001=0,"—",INDEX('1. Master BOM'!$B$1:$B$400,$L3001))) | P3001: =IF($A3001="","",IF(OR($H3001="NOT IN SCHEMATIC",$O3001="—"),"",IF($G3001="","NO SCH PN",IF(UPPER(TRIM($G3001))=UPPER(TRIM($O3001)),"OK","MISMATCH")))) | Q3001: =IF($A3001="","",IF($L3001=0,"—",INDEX('1. Master BOM'!$E$1:$E$400,$L3001))) | R3001: =IF($A3001="","",IF($L3001=0,"—",IF(T(INDEX('1. Master BOM'!$F$1:$F$400,$L3001))="","(not set)",INDEX('1. Master BOM'!$F$1:$F$400,$L3001)))) | S3001: =IF($A3001="","",IF(OR($R3001="—",$R3001="(not set)",$D3001=""),"",IF(ISNUMBER(SEARCH(SUBSTITUTE(SUBSTITUTE(SUBSTITUTE($R3001,"-",""),"_","")," ",""),SUBSTITUTE(SUBSTITUTE(SUBSTITUTE($D3001,"-",""),"_","")," ",""))),"OK","CHECK"))) | T3001: =IF($A3001="","",IF(OR($H3001="NOT IN SCHEMATIC",$I3001="MISMATCH",$J3001="MISMATCH",$P3001="MISMATCH",$M3001<>"OK"),"REVIEW","OK"))

Sheet 6. Footprint Check
A1: BOM Item | B1: EDU Mfr Number | C1: Description | D1: Expected Footprint | E1: Decal Used (Layout) | F1: # Placed | G1: Mixed Decals? | H1: Auto Check | I1: Footprint Verified | J1: Verified By | K1: Date | L1: Notes
A2: =IF('1. Master BOM'!$A2="","",'1. Master BOM'!$A2) -> 1 | B2: =IF($A2="","",'1. Master BOM'!$B2) -> EDU-100123-001 | C2: =IF($A2="","",'1. Master BOM'!$E2) -> CAP, CER, 100pF, 5%, 50V, 0402 | D2: =IF($A2="","",IF(T('1. Master BOM'!$F2)="","(not set)",'1. Master BOM'!$F2)) -> 0402 | E2: =IF($A2="","",IFERROR(INDEX('4. Tracker'!$D$2:$D$3001,MATCH($A2,'4. Tracker'!$N$2:$N$3001,0)),"—")) -> CAP0402 | F2: =IF($A2="","",COUNTIF('4. Tracker'!$N$2:$N$3001,$A2)) -> 2 | G2: =IF($A2="","",IF($F2=0,"—",IF(SUMPRODUCT(--('4. Tracker'!$N$2:$N$3001=$A2),--('4. Tracker'!$D$2:$D$3001<>$E2))>0,"MIXED","OK"))) -> OK | H2: =IF($A2="","",IF(OR($D2="(not set)",$E2="—"),"",IF(ISNUMBER(SEARCH(SUBSTITUTE(SUBSTITUTE(SUBSTITUTE($D2,"-",""),"_","")," ",""),SUBSTITUTE(SUBSTITUTE(SUBSTITUTE($E2,"-",""),"_","")," ",""))),"OK","CHECK"))) -> OK | I2: Pass | J2: AB | K2: 46217 | L2: Example row — clear I:L before use
A3: =IF('1. Master BOM'!$A3="","",'1. Master BOM'!$A3) -> 2 | B3: =IF($A3="","",'1. Master BOM'!$B3) -> EDU-100456-001 | C3: =IF($A3="","",'1. Master BOM'!$E3) -> MMIC, GaN PA, X-BAND, QFN-24 | D3: =IF($A3="","",IF(T('1. Master BOM'!$F3)="","(not set)",'1. Master BOM'!$F3)) -> QFN24 | E3: =IF($A3="","",IFERROR(INDEX('4. Tracker'!$D$2:$D$3001,MATCH($A3,'4. Tracker'!$N$2:$N$3001,0)),"—")) -> QFN24_4X4 | F3: =IF($A3="","",COUNTIF('4. Tracker'!$N$2:$N$3001,$A3)) -> 1 | G3: =IF($A3="","",IF($F3=0,"—",IF(SUMPRODUCT(--('4. Tracker'!$N$2:$N$3001=$A3),--('4. Tracker'!$D$2:$D$3001<>$E3))>0,"MIXED","OK"))) -> OK | H3: =IF($A3="","",IF(OR($D3="(not set)",$E3="—"),"",IF(ISNUMBER(SEARCH(SUBSTITUTE(SUBSTITUTE(SUBSTITUTE($D3,"-",""),"_","")," ",""),SUBSTITUTE(SUBSTITUTE(SUBSTITUTE($E3,"-",""),"_","")," ",""))),"OK","CHECK"))) -> OK
A4: =IF('1. Master BOM'!$A4="","",'1. Master BOM'!$A4) -> 3 | B4: =IF($A4="","",'1. Master BOM'!$B4) -> EDU-100789-001 | C4: =IF($A4="","",'1. Master BOM'!$E4) -> CONNECTOR, RF, SMPM, PCB MOUNT | D4: =IF($A4="","",IF(T('1. Master BOM'!$F4)="","(not set)",'1. Master BOM'!$F4)) -> SMPM | E4: =IF($A4="","",IFERROR(INDEX('4. Tracker'!$D$2:$D$3001,MATCH($A4,'4. Tracker'!$N$2:$N$3001,0)),"—")) -> SMPM_SMT | F4: =IF($A4="","",COUNTIF('4. Tracker'!$N$2:$N$3001,$A4)) -> 1 | G4: =IF($A4="","",IF($F4=0,"—",IF(SUMPRODUCT(--('4. Tracker'!$N$2:$N$3001=$A4),--('4. Tracker'!$D$2:$D$3001<>$E4))>0,"MIXED","OK"))) -> OK | H4: =IF($A4="","",IF(OR($D4="(not set)",$E4="—"),"",IF(ISNUMBER(SEARCH(SUBSTITUTE(SUBSTITUTE(SUBSTITUTE($D4,"-",""),"_","")," ",""),SUBSTITUTE(SUBSTITUTE(SUBSTITUTE($E4,"-",""),"_","")," ",""))),"OK","CHECK"))) -> OK
A5: =IF('1. Master BOM'!$A5="","",'1. Master BOM'!$A5) -> 4 | B5: =IF($A5="","",'1. Master BOM'!$B5) -> EDU-100900-001 | C5: =IF($A5="","",'1. Master BOM'!$E5) -> SCREW, M2 X 4MM, SST, PHILLIPS | D5: =IF($A5="","",IF(T('1. Master BOM'!$F5)="","(not set)",'1. Master BOM'!$F5)) -> (not set) | E5: =IF($A5="","",IFERROR(INDEX('4. Tracker'!$D$2:$D$3001,MATCH($A5,'4. Tracker'!$N$2:$N$3001,0)),"—")) -> — | F5: =IF($A5="","",COUNTIF('4. Tracker'!$N$2:$N$3001,$A5)) -> 0 | G5: =IF($A5="","",IF($F5=0,"—",IF(SUMPRODUCT(--('4. Tracker'!$N$2:$N$3001=$A5),--('4. Tracker'!$D$2:$D$3001<>$E5))>0,"MIXED","OK"))) -> — | H5: =IF($A5="","",IF(OR($D5="(not set)",$E5="—"),"",IF(ISNUMBER(SEARCH(SUBSTITUTE(SUBSTITUTE(SUBSTITUTE($D5,"-",""),"_","")," ",""),SUBSTITUTE(SUBSTITUTE(SUBSTITUTE($E5,"-",""),"_","")," ",""))),"OK","CHECK")))
A6: =IF('1. Master BOM'!$A6="","",'1. Master BOM'!$A6) | B6: =IF($A6="","",'1. Master BOM'!$B6) | C6: =IF($A6="","",'1. Master BOM'!$E6) | D6: =IF($A6="","",IF(T('1. Master BOM'!$F6)="","(not set)",'1. Master BOM'!$F6)) | E6: =IF($A6="","",IFERROR(INDEX('4. Tracker'!$D$2:$D$3001,MATCH($A6,'4. Tracker'!$N$2:$N$3001,0)),"—")) | F6: =IF($A6="","",COUNTIF('4. Tracker'!$N$2:$N$3001,$A6)) | G6: =IF($A6="","",IF($F6=0,"—",IF(SUMPRODUCT(--('4. Tracker'!$N$2:$N$3001=$A6),--('4. Tracker'!$D$2:$D$3001<>$E6))>0,"MIXED","OK"))) | H6: =IF($A6="","",IF(OR($D6="(not set)",$E6="—"),"",IF(ISNUMBER(SEARCH(SUBSTITUTE(SUBSTITUTE(SUBSTITUTE($D6,"-",""),"_","")," ",""),SUBSTITUTE(SUBSTITUTE(SUBSTITUTE($E6,"-",""),"_","")," ",""))),"OK","CHECK")))
A7: =IF('1. Master BOM'!$A7="","",'1. Master BOM'!$A7) | B7: =IF($A7="","",'1. Master BOM'!$B7) | C7: =IF($A7="","",'1. Master BOM'!$E7) | D7: =IF($A7="","",IF(T('1. Master BOM'!$F7)="","(not set)",'1. Master BOM'!$F7)) | E7: =IF($A7="","",IFERROR(INDEX('4. Tracker'!$D$2:$D$3001,MATCH($A7,'4. Tracker'!$N$2:$N$3001,0)),"—")) | F7: =IF($A7="","",COUNTIF('4. Tracker'!$N$2:$N$3001,$A7)) | G7: =IF($A7="","",IF($F7=0,"—",IF(SUMPRODUCT(--('4. Tracker'!$N$2:$N$3001=$A7),--('4. Tracker'!$D$2:$D$3001<>$E7))>0,"MIXED","OK"))) | H7: =IF($A7="","",IF(OR($D7="(not set)",$E7="—"),"",IF(ISNUMBER(SEARCH(SUBSTITUTE(SUBSTITUTE(SUBSTITUTE($D7,"-",""),"_","")," ",""),SUBSTITUTE(SUBSTITUTE(SUBSTITUTE($E7,"-",""),"_","")," ",""))),"OK","CHECK")))
A8: =IF('1. Master BOM'!$A8="","",'1. Master BOM'!$A8) | B8: =IF($A8="","",'1. Master BOM'!$B8) | C8: =IF($A8="","",'1. Master BOM'!$E8) | D8: =IF($A8="","",IF(T('1. Master BOM'!$F8)="","(not set)",'1. Master BOM'!$F8)) | E8: =IF($A8="","",IFERROR(INDEX('4. Tracker'!$D$2:$D$3001,MATCH($A8,'4. Tracker'!$N$2:$N$3001,0)),"—")) | F8: =IF($A8="","",COUNTIF('4. Tracker'!$N$2:$N$3001,$A8)) | G8: =IF($A8="","",IF($F8=0,"—",IF(SUMPRODUCT(--('4. Tracker'!$N$2:$N$3001=$A8),--('4. Tracker'!$D$2:$D$3001<>$E8))>0,"MIXED","OK"))) | H8: =IF($A8="","",IF(OR($D8="(not set)",$E8="—"),"",IF(ISNUMBER(SEARCH(SUBSTITUTE(SUBSTITUTE(SUBSTITUTE($D8,"-",""),"_","")," ",""),SUBSTITUTE(SUBSTITUTE(SUBSTITUTE($E8,"-",""),"_","")," ",""))),"OK","CHECK")))
A9: =IF('1. Master BOM'!$A9="","",'1. Master BOM'!$A9) | B9: =IF($A9="","",'1. Master BOM'!$B9) | C9: =IF($A9="","",'1. Master BOM'!$E9) | D9: =IF($A9="","",IF(T('1. Master BOM'!$F9)="","(not set)",'1. Master BOM'!$F9)) | E9: =IF($A9="","",IFERROR(INDEX('4. Tracker'!$D$2:$D$3001,MATCH($A9,'4. Tracker'!$N$2:$N$3001,0)),"—")) | F9: =IF($A9="","",COUNTIF('4. Tracker'!$N$2:$N$3001,$A9)) | G9: =IF($A9="","",IF($F9=0,"—",IF(SUMPRODUCT(--('4. Tracker'!$N$2:$N$3001=$A9),--('4. Tracker'!$D$2:$D$3001<>$E9))>0,"MIXED","OK"))) | H9: =IF($A9="","",IF(OR($D9="(not set)",$E9="—"),"",IF(ISNUMBER(SEARCH(SUBSTITUTE(SUBSTITUTE(SUBSTITUTE($D9,"-",""),"_","")," ",""),SUBSTITUTE(SUBSTITUTE(SUBSTITUTE($E9,"-",""),"_","")," ",""))),"OK","CHECK")))
